Workbook

Sheet MapeoImpactosComandos
A1: Mapa impacto | D1: Objeto de dominio | E1: Event Storming | G1: Mapeo consistente | H1: Observaciones | I1: Historia de usuario
A2: Actor | B2: Impacto | C2: Entregable | E2: Actor | F2: Comando
A3: Actor | B3: Valor de negocio | C3: Épica | E3: Actor | F3: Funcionalidad/Historia Usuario | I3: Identificador | J3: Nombre | K3: Card | L3: Talla(Tamaño) | M3: Talla(Complejidad) | N3: Pivote | O3: Orden | P3: Como | Q3: Necesito | R3: Para
A4: Administradores del Sistema | B4: Permitir la gestión de los entrenadores e informes generados por la aplicación, para facilitar la supervisión y el seguimiento de los procesos. | C4: Gestión de entrenadores | D4: Entrenador | E4: Administrador del sistema | F4: Registrar información de un nuevo entrenador | G4: SI | I4: HU-BASE-001 | J4: =_xlfn.CONCAT(I4,"-",F4) -> HU-BASE-001-Registrar información de un nuevo entrenador | K4: =_xlfn.CONCAT($P$3," ",P4," ",$Q$3," ",Q4," ",$R$3," ",R4) -> Como Administrador del sistema Necesito Registrar información de un nuevo entrenador Para Permitir la gestión de los entrenadores e informes generados por la aplicación, para facilitar la supervisión y el seguimiento de los procesos. | L4: S | M4: S | N4: SI | P4: =E4 -> Administrador del sistema | Q4: =F4 -> Registrar información de un nuevo entrenador | R4: =B4 -> Permitir la gestión de los entrenadores e informes generados por la aplicación, para facilitar la supervisión y el seguimiento de los procesos.
A5: Estudiantes | B5: Realizar los diferentes entrenamientos cognitivos asignados, con el fin de mejorar las habilidades cognitivas en las que se haya identificado una oportunidad de desarrollo en el estudiante. ​ | C5: Ejecución de planes de entrenamiento | D5: Entrenamiento Cognitivo | E5: Estudiante | F5: Comenzar un entrenamiento cognitivo | G5: SI | I5: HU-BASE-002 | J5: =_xlfn.CONCAT(I5,"-",F5) -> HU-BASE-002-Comenzar un entrenamiento cognitivo | K5: =_xlfn.CONCAT($P$3," ",P5," ",$Q$3," ",Q5," ",$R$3," ",R5) -> Como Estudiante Necesito poder iniciar el proceso de mi entrenamiento cognitivo Para Realizar los diferentes entrenamientos cognitivos asignados, con el fin de mejorar las habilidades cognitivas en las que se haya identificado una oportunidad de desarrollo en el estudiante. ​ | L5: S | M5: M | P5: Estudiante | Q5: poder iniciar el proceso de mi entrenamiento cognitivo | R5: =B5 -> Realizar los diferentes entrenamientos cognitivos asignados, con el fin de mejorar las habilidades cognitivas en las que se haya identificado una oportunidad de desarrollo en el estudiante. ​
A6: Entrenadores | B6: Permitir la gestión de los estudiantes, dando el acceso a planes de entrenamiento, así como visualizar el progreso de los planes que desarrolle, lo que le concede la capacidad de medir su rendimiento en las diferentes planes de entrenamiento, ver el progreso del estudiante por medio de métricas, también visualizar el uso de la aplicación y la satisfacción de los estudiantes en el desarrollo del programa. | C6: Gestión de Entrenamientos Cognitivos | D6: Sesión Entrenamiento | E6: Entrenador | F6: Dar acceso a entrenamiento cognitivo | G6: SI | I6: HU-BASE-003 | J6: =_xlfn.CONCAT(I6,"-",F6) -> HU-BASE-003-Dar acceso a entrenamiento cognitivo | K6: =_xlfn.CONCAT($P$3," ",P6," ",$Q$3," ",Q6," ",$R$3," ",R6) -> Como Entrenador Necesito brindar acceso a los estudiantes a los diferentes entrenamientos cognitivos Para Permitir la gestión de los estudiantes, dando el acceso a planes de entrenamiento, así como visualizar el progreso de los planes que desarrolle, lo que le concede la capacidad de medir su rendimiento en las diferentes planes de entrenamiento, ver el progreso del estudiante por medio de métricas, también visualizar el uso de la aplicación y la satisfacción de los estudiantes en el desarrollo del programa. | L6: S | M6: M | P6: Entrenador | Q6: brindar acceso a los estudiantes a los diferentes entrenamientos cognitivos | R6: =B6 -> Permitir la gestión de los estudiantes, dando el acceso a planes de entrenamiento, así como visualizar el progreso de los planes que desarrolle, lo que le concede la capacidad de medir su rendimiento en las diferentes planes de entrenamiento, ver el progreso del estudiante por medio de métricas, también visualizar el uso de la aplicación y la satisfacción de los estudiantes en el desarrollo del programa.
A7: Entrenadores | B7: Permitir la gestión de los estudiantes, dando el acceso a planes de entrenamiento, así como visualizar el progreso de los planes que desarrolle, lo que le concede la capacidad de medir su rendimiento en las diferentes planes de entrenamiento, ver el progreso del estudiante por medio de métricas, también visualizar el uso de la aplicación y la satisfacción de los estudiantes en el desarrollo del programa. | C7: Gestión de Informes​ | D7: Entrenamiento Cognitivo | E7: Entrenador | F7: Generar informes de entrenamientos cognitivos creados asignados | G7: SI | I7: HU-BASE-004 | J7: =_xlfn.CONCAT(I7,"-",F7) -> HU-BASE-004-Generar informes de entrenamientos cognitivos creados asignados | K7: =_xlfn.CONCAT($P$3," ",P7," ",$Q$3," ",Q7," ",$R$3," ",R7) -> Como Entrenador Necesito poder generar informes de los entrenamientos cognitivos asignados Para Permitir la gestión de los estudiantes, dando el acceso a planes de entrenamiento, así como visualizar el progreso de los planes que desarrolle, lo que le concede la capacidad de medir su rendimiento en las diferentes planes de entrenamiento, ver el progreso del estudiante por medio de métricas, también visualizar el uso de la aplicación y la satisfacción de los estudiantes en el desarrollo del programa. | L7: M | M7: S | P7: =E7 -> Entrenador | Q7: poder generar informes de los entrenamientos cognitivos asignados | R7: =B7 -> Permitir la gestión de los estudiantes, dando el acceso a planes de entrenamiento, así como visualizar el progreso de los planes que desarrolle, lo que le concede la capacidad de medir su rendimiento en las diferentes planes de entrenamiento, ver el progreso del estudiante por medio de métricas, también visualizar el uso de la aplicación y la satisfacción de los estudiantes en el desarrollo del programa.
A8: Entrenadores | B8: Permitir la gestión de los estudiantes, dando el acceso a planes de entrenamiento, así como visualizar el progreso de los planes que desarrolle, lo que le concede la capacidad de medir su rendimiento en las diferentes planes de entrenamiento, ver el progreso del estudiante por medio de métricas, también visualizar el uso de la aplicación y la satisfacción de los estudiantes en el desarrollo del programa. | C8: Gestión de Informes | D8: Asignación Variable Cognitiva | E8: Entrenador | F8: Consultar historial de entrenamiento cognitivo | G8: SI | I8: HU-BASE-005 | J8: =_xlfn.CONCAT(I8,"-",F8) -> HU-BASE-005-Consultar historial de entrenamiento cognitivo | K8: =_xlfn.CONCAT($P$3," ",P8," ",$Q$3," ",Q8," ",$R$3," ",R8) -> Como Entrenador Necesito poder consultar el historial de actividad de los diferentes entrenamientos cognitivos Para Permitir la gestión de los estudiantes, dando el acceso a planes de entrenamiento, así como visualizar el progreso de los planes que desarrolle, lo que le concede la capacidad de medir su rendimiento en las diferentes planes de entrenamiento, ver el progreso del estudiante por medio de métricas, también visualizar el uso de la aplicación y la satisfacción de los estudiantes en el desarrollo del programa. | L8: XS | M8: S | P8: =E8 -> Entrenador | Q8: poder consultar el historial de actividad de los diferentes entrenamientos cognitivos | R8: =B8 -> Permitir la gestión de los estudiantes, dando el acceso a planes de entrenamiento, así como visualizar el progreso de los planes que desarrolle, lo que le concede la capacidad de medir su rendimiento en las diferentes planes de entrenamiento, ver el progreso del estudiante por medio de métricas, también visualizar el uso de la aplicación y la satisfacción de los estudiantes en el desarrollo del programa.
A9: Entrenadores | B9: Permitir la gestión de los estudiantes, dando el acceso a planes de entrenamiento, así como visualizar el progreso de los planes que desarrolle, lo que le concede la capacidad de medir su rendimiento en las diferentes planes de entrenamiento, ver el progreso del estudiante por medio de métricas, también visualizar el uso de la aplicación y la satisfacción de los estudiantes en el desarrollo del programa. | C9: Gestión de Entrenamientos Cognitivos | D9: Entrenamiento Cognitivo | E9: Entrenador | F9: Crear un nuevo entrenamiento cognitivo | G9: SI | I9: HU-BASE-006 | J9: =_xlfn.CONCAT(I9,"-",F9) -> HU-BASE-006-Crear un nuevo entrenamiento cognitivo | K9: =_xlfn.CONCAT($P$3," ",P9," ",$Q$3," ",Q9," ",$R$3," ",R9) -> Como Entrenador Necesito poder crear un nuevo entrenamiento cognitivo Para Permitir la gestión de los estudiantes, dando el acceso a planes de entrenamiento, así como visualizar el progreso de los planes que desarrolle, lo que le concede la capacidad de medir su rendimiento en las diferentes planes de entrenamiento, ver el progreso del estudiante por medio de métricas, también visualizar el uso de la aplicación y la satisfacción de los estudiantes en el desarrollo del programa. | L9: S | M9: M | P9: =E9 -> Entrenador | Q9: poder crear un nuevo entrenamiento cognitivo | R9: =B9 -> Permitir la gestión de los estudiantes, dando el acceso a planes de entrenamiento, así como visualizar el progreso de los planes que desarrolle, lo que le concede la capacidad de medir su rendimiento en las diferentes planes de entrenamiento, ver el progreso del estudiante por medio de métricas, también visualizar el uso de la aplicación y la satisfacción de los estudiantes en el desarrollo del programa.
A10: Entrenadores | B10: Permitir la gestión de los estudiantes, dando el acceso a planes de entrenamiento, así como visualizar el progreso de los planes que desarrolle, lo que le concede la capacidad de medir su rendimiento en las diferentes planes de entrenamiento, ver el progreso del estudiante por medio de métricas, también visualizar el uso de la aplicación y la satisfacción de los estudiantes en el desarrollo del programa. | C10: Gestión de Entrenamientos Cognitivos | D10: Entrenamiento Cognitivo | E10: Entrenador | F10: Modificar un entrenamiento cognitivo | G10: SI | I10: HU-BASE-007 | J10: =_xlfn.CONCAT(I10,"-",F10) -> HU-BASE-007-Modificar un entrenamiento cognitivo | K10: =_xlfn.CONCAT($P$3," ",P10," ",$Q$3," ",Q10," ",$R$3," ",R10) -> Como Entrenador Necesito poder editar un entrenamiento cognitivo Para Permitir la gestión de los estudiantes, dando el acceso a planes de entrenamiento, así como visualizar el progreso de los planes que desarrolle, lo que le concede la capacidad de medir su rendimiento en las diferentes planes de entrenamiento, ver el progreso del estudiante por medio de métricas, también visualizar el uso de la aplicación y la satisfacción de los estudiantes en el desarrollo del programa. | L10: S | M10: M | P10: =E10 -> Entrenador | Q10: poder editar un entrenamiento cognitivo | R10: =B10 -> Permitir la gestión de los estudiantes, dando el acceso a planes de entrenamiento, así como visualizar el progreso de los planes que desarrolle, lo que le concede la capacidad de medir su rendimiento en las diferentes planes de entrenamiento, ver el progreso del estudiante por medio de métricas, también visualizar el uso de la aplicación y la satisfacción de los estudiantes en el desarrollo del programa.
A11: Entrenadores | B11: Permitir la gestión de los estudiantes, dando el acceso a planes de entrenamiento, así como visualizar el progreso de los planes que desarrolle, lo que le concede la capacidad de medir su rendimiento en las diferentes planes de entrenamiento, ver el progreso del estudiante por medio de métricas, también visualizar el uso de la aplicación y la satisfacción de los estudiantes en el desarrollo del programa. | C11: Gestión de Entrenamientos Cognitivos | D11: Sesión Entrenamiento | E11: Entrenador | F11: Iniciar sesion de entrenamiento | G11: SI | I11: HU-BASE-008 | J11: =_xlfn.CONCAT(I11,"-",F11) -> HU-BASE-008-Iniciar sesion de entrenamiento | K11: =_xlfn.CONCAT($P$3," ",P11," ",$Q$3," ",Q11," ",$R$3," ",R11) -> Como Entrenador Necesito poder iniciar una nueva sesión de entrenamiento inmediatamente Para Permitir la gestión de los estudiantes, dando el acceso a planes de entrenamiento, así como visualizar el progreso de los planes que desarrolle, lo que le concede la capacidad de medir su rendimiento en las diferentes planes de entrenamiento, ver el progreso del estudiante por medio de métricas, también visualizar el uso de la aplicación y la satisfacción de los estudiantes en el desarrollo del programa. | L11: S | M11: S | P11: =E11 -> Entrenador | Q11: poder iniciar una nueva sesión de entrenamiento inmediatamente | R11: =B11 -> Permitir la gestión de los estudiantes, dando el acceso a planes de entrenamiento, así como visualizar el progreso de los planes que desarrolle, lo que le concede la capacidad de medir su rendimiento en las diferentes planes de entrenamiento, ver el progreso del estudiante por medio de métricas, también visualizar el uso de la aplicación y la satisfacción de los estudiantes en el desarrollo del programa.
A12: Estudiantes | B12: Realizar los diferentes entrenamientos cognitivos asignados, con el fin de mejorar las habilidades cognitivas en las que se haya identificado una oportunidad de desarrollo en el estudiante. ​ | C12: Ejecución de planes de entrenamiento | D12: Asignación Variable Cognitiva | E12: Estudiante | F12: Ingresar a una variable cognitiva a la que tenga acceso | G12: SI | I12: HU-BASE-009 | J12: =_xlfn.CONCAT(I12,"-",F12) -> HU-BASE-009-Ingresar a una variable cognitiva a la que tenga acceso | K12: =_xlfn.CONCAT($P$3," ",P12," ",$Q$3," ",Q12," ",$R$3," ",R12) -> Como Estudiante Necesito poder ingresar a una variable cognitiva a la que tenga acceso Para Realizar los diferentes entrenamientos cognitivos asignados, con el fin de mejorar las habilidades cognitivas en las que se haya identificado una oportunidad de desarrollo en el estudiante. ​ | L12: S | M12: S | P12: =E12 -> Estudiante | Q12: poder ingresar a una variable cognitiva a la que tenga acceso | R12: =B12 -> Realizar los diferentes entrenamientos cognitivos asignados, con el fin de mejorar las habilidades cognitivas en las que se haya identificado una oportunidad de desarrollo en el estudiante. ​
A13: Estudiantes | B13: Realizar los diferentes entrenamientos cognitivos asignados, con el fin de mejorar las habilidades cognitivas en las que se haya identificado una oportunidad de desarrollo en el estudiante. ​ | C13: Ejecución de planes de entrenamiento | D13: Asignación Variable Cognitiva | E13: Estudiante | F13: Abandonar variable cognitiva | G13: SI | I13: HU-BASE-010 | J13: =_xlfn.CONCAT(I13,"-",F13) -> HU-BASE-010-Abandonar variable cognitiva | K13: =_xlfn.CONCAT($P$3," ",P13," ",$Q$3," ",Q13," ",$R$3," ",R13) -> Como Estudiante Necesito poder abandonar el entrenamiento cognitivo que esté desarrollando Para Realizar los diferentes entrenamientos cognitivos asignados, con el fin de mejorar las habilidades cognitivas en las que se haya identificado una oportunidad de desarrollo en el estudiante. ​ | L13: XS | M13: XS | P13: =E13 -> Estudiante | Q13: poder abandonar el entrenamiento cognitivo que esté desarrollando | R13: =B13 -> Realizar los diferentes entrenamientos cognitivos asignados, con el fin de mejorar las habilidades cognitivas en las que se haya identificado una oportunidad de desarrollo en el estudiante. ​
A14: Entrenadores | B14: Permitir la gestión de los estudiantes, dando el acceso a planes de entrenamiento, así como visualizar el progreso de los planes que desarrolle, lo que le concede la capacidad de medir su rendimiento en las diferentes planes de entrenamiento, ver el progreso del estudiante por medio de métricas, también visualizar el uso de la aplicación y la satisfacción de los estudiantes en el desarrollo del programa. | C14: Gestión de Estudiantes | D14: Estudiante | E14: Entrenador | F14: Registrar un nuevo estudiante | G14: SI | I14: HU-BASE-011 | J14: =_xlfn.CONCAT(I14,"-",F14) -> HU-BASE-011-Registrar un nuevo estudiante | K14: =_xlfn.CONCAT($P$3," ",P14," ",$Q$3," ",Q14," ",$R$3," ",R14) -> Como Entrenador Necesito poder registrar a un nuevo estudiante remitido por pedagogos Para Permitir la gestión de los estudiantes, dando el acceso a planes de entrenamiento, así como visualizar el progreso de los planes que desarrolle, lo que le concede la capacidad de medir su rendimiento en las diferentes planes de entrenamiento, ver el progreso del estudiante por medio de métricas, también visualizar el uso de la aplicación y la satisfacción de los estudiantes en el desarrollo del programa. | L14: S | M14: S | P14: =E14 -> Entrenador | Q14: poder registrar a un nuevo estudiante remitido por pedagogos | R14: =B14 -> Permitir la gestión de los estudiantes, dando el acceso a planes de entrenamiento, así como visualizar el progreso de los planes que desarrolle, lo que le concede la capacidad de medir su rendimiento en las diferentes planes de entrenamiento, ver el progreso del estudiante por medio de métricas, también visualizar el uso de la aplicación y la satisfacción de los estudiantes en el desarrollo del programa.
A15: Entrenadores | B15: Permitir la gestión de los estudiantes, dando el acceso a planes de entrenamiento, así como visualizar el progreso de los planes que desarrolle, lo que le concede la capacidad de medir su rendimiento en las diferentes planes de entrenamiento, ver el progreso del estudiante por medio de métricas, también visualizar el uso de la aplicación y la satisfacción de los estudiantes en el desarrollo del programa. | C15: Gestión de Entrenamientos Cognitivos | D15: Asignación Variable Cognitiva | E15: Entrenador | F15: Aprobar abandono de variable cognitiva del estudiante | G15: SI | I15: HU-BASE-012 | J15: =_xlfn.CONCAT(I15,"-",F15) -> HU-BASE-012-Aprobar abandono de variable cognitiva del estudiante | K15: =_xlfn.CONCAT($P$3," ",P15," ",$Q$3," ",Q15," ",$R$3," ",R15) -> Como Entrenador Necesito poder aprobar el abandono de un estudiante Para Permitir la gestión de los estudiantes, dando el acceso a planes de entrenamiento, así como visualizar el progreso de los planes que desarrolle, lo que le concede la capacidad de medir su rendimiento en las diferentes planes de entrenamiento, ver el progreso del estudiante por medio de métricas, también visualizar el uso de la aplicación y la satisfacción de los estudiantes en el desarrollo del programa. | L15: XS | M15: XS | P15: =E15 -> Entrenador | Q15: poder aprobar el abandono de un estudiante | R15: =B15 -> Permitir la gestión de los estudiantes, dando el acceso a planes de entrenamiento, así como visualizar el progreso de los planes que desarrolle, lo que le concede la capacidad de medir su rendimiento en las diferentes planes de entrenamiento, ver el progreso del estudiante por medio de métricas, también visualizar el uso de la aplicación y la satisfacción de los estudiantes en el desarrollo del programa.
A16: Administradores del Sistema | B16: Permitir la gestión de los entrenadores e informes generados por la aplicación, para facilitar la supervisión y el seguimiento de los procesos. | C16: Gestión de Informes | D16: Entrenamiento Cognitivo | E16: Administrador del sistema | F16: Generar informes de entrenamientos cognitivos creados | G16: SI | I16: HU-BASE-013 | J16: =_xlfn.CONCAT(I16,"-",F16) -> HU-BASE-013-Generar informes de entrenamientos cognitivos creados | K16: =_xlfn.CONCAT($P$3," ",P16," ",$Q$3," ",Q16," ",$R$3," ",R16) -> Como Administrador del sistema Necesito poder generar informes de los entrenamientos cognitivos Para Permitir la gestión de los entrenadores e informes generados por la aplicación, para facilitar la supervisión y el seguimiento de los procesos. | L16: M | M16: S | P16: =E16 -> Administrador del sistema | Q16: poder generar informes de los entrenamientos cognitivos | R16: =B16 -> Permitir la gestión de los entrenadores e informes generados por la aplicación, para facilitar la supervisión y el seguimiento de los procesos.
A17: Entrenadores | B17: Permitir la gestión de los estudiantes, dando el acceso a planes de entrenamiento, así como visualizar el progreso de los planes que desarrolle, lo que le concede la capacidad de medir su rendimiento en las diferentes planes de entrenamiento, ver el progreso del estudiante por medio de métricas, también visualizar el uso de la aplicación y la satisfacción de los estudiantes en el desarrollo del programa. | C17: Gestión de Informes | D17: Sesión Entrenamiento | E17: Entrenador | F17: Crear observación de sesión de entrenamiento | G17: SI | I17: HU-BASE-014 | J17: =_xlfn.CONCAT(I17,"-",F17) -> HU-BASE-014-Crear observación de sesión de entrenamiento | K17: =_xlfn.CONCAT($P$3," ",P17," ",$Q$3," ",Q17," ",$R$3," ",R17) -> Como Entrenador Necesito poder generar comentarios sobre la sesión de un estudiante en su entrenamiento cognitivo Para Permitir la gestión de los estudiantes, dando el acceso a planes de entrenamiento, así como visualizar el progreso de los planes que desarrolle, lo que le concede la capacidad de medir su rendimiento en las diferentes planes de entrenamiento, ver el progreso del estudiante por medio de métricas, también visualizar el uso de la aplicación y la satisfacción de los estudiantes en el desarrollo del programa. | L17: S | M17: S | P17: =E17 -> Entrenador | Q17: poder generar comentarios sobre la sesión de un estudiante en su entrenamiento cognitivo | R17: =B17 -> Permitir la gestión de los estudiantes, dando el acceso a planes de entrenamiento, así como visualizar el progreso de los planes que desarrolle, lo que le concede la capacidad de medir su rendimiento en las diferentes planes de entrenamiento, ver el progreso del estudiante por medio de métricas, también visualizar el uso de la aplicación y la satisfacción de los estudiantes en el desarrollo del programa.
A18: Administradores del Sistema | B18: Permitir la gestión de los entrenadores e informes generados por la aplicación, para facilitar la supervisión y el seguimiento de los procesos. | C18: Gestión de Entrenadores | D18: Entrenador | E18: Administrador del sistema | F18: Modificar información de entrenadores | G18: SI | I18: HU-BASE-015 | J18: =_xlfn.CONCAT(I18,"-",F18) -> HU-BASE-015-Modificar información de entrenadores | K18: =_xlfn.CONCAT($P$3," ",P18," ",$Q$3," ",Q18," ",$R$3," ",R18) -> Como Administrador del sistema Necesito poder modificar a los entrenadores de la aplicación Para Permitir la gestión de los entrenadores e informes generados por la aplicación, para facilitar la supervisión y el seguimiento de los procesos. | L18: S | M18: S | P18: =E18 -> Administrador del sistema | Q18: poder modificar a los entrenadores de la aplicación | R18: =B18 -> Permitir la gestión de los entrenadores e informes generados por la aplicación, para facilitar la supervisión y el seguimiento de los procesos.
... A26: Entrenadores | B26: Permitir la gestión de los estudiantes, dando el acceso a planes de entrenamiento, así como visualizar el progreso de los planes que desarrolle, lo que le concede la capacidad de medir su rendimiento en las diferentes planes de entrenamiento, ver el progreso del estudiante por medio de métricas, también visualizar el uso de la aplicación y la satisfacción de los estudiantes en el desarrollo del programa. | C26: Gestión de Informes | D26: Entrenamiento Cognitivo | E26: Entrenador | F26: Descargar informe de entrenamiento cognitivo | G26: SI | I26: HU-BASE-023 | J26: =_xlfn.CONCAT(I26,"-",F26) -> HU-BASE-023-Descargar informe de entrenamiento cognitivo | K26: =_xlfn.CONCAT($P$3," ",P26," ",$Q$3," ",Q26," ",$R$3," ",R26) -> Como Entrenador Necesito poder descargar el informe del entrenamiento cognitivo Para Permitir la gestión de los estudiantes, dando el acceso a planes de entrenamiento, así como visualizar el progreso de los planes que desarrolle, lo que le concede la capacidad de medir su rendimiento en las diferentes planes de entrenamiento, ver el progreso del estudiante por medio de métricas, también visualizar el uso de la aplicación y la satisfacción de los estudiantes en el desarrollo del programa. | L26: S | M26: S | P26: =E26 -> Entrenador | Q26: poder descargar el informe del entrenamiento cognitivo | R26: =B26 -> Permitir la gestión de los estudiantes, dando el acceso a planes de entrenamiento, así como visualizar el progreso de los planes que desarrolle, lo que le concede la capacidad de medir su rendimiento en las diferentes planes de entrenamiento, ver el progreso del estudiante por medio de métricas, también visualizar el uso de la aplicación y la satisfacción de los estudiantes en el desarrollo del programa.

Sheet HU-BASE-001
A1: <-Volver al listado
A2: Título
A3: =MapeoImpactosComandos!J4 -> HU-BASE-001-Registrar información de un nuevo entrenador
A4: Tarjeta
A5: Como | B5: =MapeoImpactosComandos!P4 -> Administrador del sistema
A6: Necesito | B6: =MapeoImpactosComandos!Q4 -> Registrar información de un nuevo entrenador
A7: Para | B7: =MapeoImpactosComandos!R4 -> Permitir la gestión de los entrenadores e informes generados por la aplicación, para facilitar la supervisión y el seguimiento de los procesos.
A8: =MapeoImpactosComandos!K4 -> Como Administrador del sistema Necesito Registrar información de un nuevo entrenador Para Permitir la gestión de los entrenadores e informes generados por la aplicación, para facilitar la supervisión y el seguimiento de los procesos.
A9: Tallaje
A10: =MapeoImpactosComandos!L3 -> Talla(Tamaño) | E10: =MapeoImpactosComandos!L4 -> S
A11: =MapeoImpactosComandos!M3 -> Talla(Complejidad) | E11: =MapeoImpactosComandos!M4 -> S
A12: ¿Definition of Ready? | E12: SI
A13: ¿Definition of Done? | E13: SI
A14: Criterios aceptación
A15: Código | B15: Escenario | G15: Estado | I15: Observación
G16: Aceptado | H16: No aceptado
A17: CA1 | B17: Dado que un Administrador del sistema está autenticado en la plataforma. Cuando envía la información completa y válida de un nuevo entrenador (nombres, apellidos, tipo y número de documento, correo y al menos una facultad válida). Entonces el sistema debe registrar al nuevo entrenador en la base de datos y responder con un mensaje de éxito y el ID del nuevo registro. | G17: X
A18: CA2 | B18: Dado que un Administrador del sistema está autenticado. Cuando intenta registrar un nuevo entrenador con un número de documento que ya existe en el sistema. Entonces el sistema debe rechazar la solicitud y mostrar un mensaje de error indicando que el documento ya está en uso. | G18: X
A19: CA3 | B19: Dado que un Administrador del sistema está autenticado. Cuando intenta registrar un nuevo entrenador con una dirección de correo electrónico que ya existe en el sistema. Entonces el sistema debe rechazar la solicitud y mostrar un mensaje de error indicando que el correo electrónico ya está registrado. | G19: X
A20: CA4 | B20: Dado que un Administrador del sistema está autenticado. Cuando intenta registrar un nuevo entrenador asignándole una facultad que no existe en el sistema. Entonces el sistema debe rechazar la solicitud y mostrar un mensaje de error indicando que la facultad no es válida. | G20: X
A21: CA5 | B21: Dado que un Administrador del sistema está autenticado. Cuando intenta registrar un nuevo entrenador sin proporcionar todos los campos obligatorios (por ejemplo, el campo "nombres"). Entonces el sistema debe rechazar la solicitud y mostrar un mensaje de error que especifique cuál campo obligatorio falta. | G21: X
A22: CA6 | B22: Dado que un usuario autenticado que no tiene el rol de "Administrador" intenta acceder a la funcionalidad. Cuando envía una solicitud para registrar un nuevo entrenador. Entonces el sistema debe denegar el acceso y responder con un mensaje de error de permisos insuficientes. | G22: X

Sheet HU-BASE-002
A1: <-Volver al listado
A2: Título
A3: =MapeoImpactosComandos!J5 -> HU-BASE-002-Comenzar un entrenamiento cognitivo
A4: Tarjeta
A5: Como | B5: =MapeoImpactosComandos!P5 -> Estudiante
A6: Necesito | B6: =MapeoImpactosComandos!Q5 -> poder iniciar el proceso de mi entrenamiento cognitivo
A7: Para | B7: =MapeoImpactosComandos!R5 -> Realizar los diferentes entrenamientos cognitivos asignados, con el fin de mejorar las habilidades cognitivas en las que se haya identificado una oportunidad de desarrollo en el estudiante. ​
A8: =MapeoImpactosComandos!K5 -> Como Estudiante Necesito poder iniciar el proceso de mi entrenamiento cognitivo Para Realizar los diferentes entrenamientos cognitivos asignados, con el fin de mejorar las habilidades cognitivas en las que se haya identificado una oportunidad de desarrollo en el estudiante. ​
A9: Tallaje
A10: =MapeoImpactosComandos!L3 -> Talla(Tamaño) | E10: =MapeoImpactosComandos!L5 -> S
A11: =MapeoImpactosComandos!M3 -> Talla(Complejidad) | E11: =MapeoImpactosComandos!M5 -> M
A12: ¿Definition of Ready? | E12: SI
A13: ¿Definition of Done? | E13: SI
A14: Criterios aceptación
A15: Código | B15: Escenario | G15: Estado | I15: Observación
G16: Aceptado | H16: No aceptado
A17: CA1 | B17: Dado que un Estudiante ha iniciado una sesion de entrenado y tiene el estado "Por Iniciar". Cuando el entrenador selecciona la opción para comenzar dicha sesión. Entonces el sistema debe cambiar el estado de la sesión a "En Progreso" y presentarle la primera actividad o tarea correspondiente a esa sesión. | G17: X
A18: CA2 | B18: Dado que un Estudiante inicia su primera sesión de un entrenamiento cognitivo. Cuando la sesión cambia a estado "En Progreso". Entonces el sistema debe actualizar automáticamente el estado general del "Entrenamiento Cognitivo" y el de la "Variable Cognitiva" asociada a "En Progreso". | G18: X

Sheet HU-BASE-003
A1: <-Volver al listado
A2: Título
A3: =MapeoImpactosComandos!J6 -> HU-BASE-003-Dar acceso a entrenamiento cognitivo
A4: Tarjeta
A5: Como | B5: =MapeoImpactosComandos!P6 -> Entrenador
A6: Necesito | B6: =MapeoImpactosComandos!Q6 -> brindar acceso a los estudiantes a los diferentes entrenamientos cognitivos
A7: Para | B7: =MapeoImpactosComandos!R6 -> Permitir la gestión de los estudiantes, dando el acceso a planes de entrenamiento, así como visualizar el progreso de los planes que desarrolle, lo que le concede la capacidad de medir su rendimiento en las diferentes planes de entrenamiento, ver el progreso del estudiante por medio de métricas, también visualizar el uso de la aplicación y la satisfacción de los estudiantes en el desarrollo del programa.
A8: =MapeoImpactosComandos!K6 -> Como Entrenador Necesito brindar acceso a los estudiantes a los diferentes entrenamientos cognitivos Para Permitir la gestión de los estudiantes, dando el acceso a planes de entrenamiento, así como visualizar el progreso de los planes que desarrolle, lo que le concede la capacidad de medir su rendimiento en las diferentes planes de entrenamiento, ver el progreso del estudiante por medio de métricas, también visualizar el uso de la aplicación y la satisfacción de los estudiantes en el desarrollo del programa.
A9: Tallaje
A10: =MapeoImpactosComandos!L3 -> Talla(Tamaño) | E10: =MapeoImpactosComandos!L6 -> S
A11: =MapeoImpactosComandos!M3 -> Talla(Complejidad) | E11: =MapeoImpactosComandos!M6 -> M
A12: ¿Definition of Ready? | E12: SI
A13: ¿Definition of Done? | E13: SI
A14: Criterios aceptación
A15: Código | B15: Escenario | G15: Estado | I15: Observación
G16: Aceptado | H16: No aceptado
A17: CA1 | B17: Dado que un Entrenador intenta crear un entrenamiento. Cuando ingrese la información completa del estudiante y sus variables. Entonces el sistema notificar la creacion existosa del entrenamiento. | G17: X
A18: CA2 | B18: Dado que un Entrenador está en el formulario de creación de entrenamiento. Cuando intenta asignar el entrenamiento a un estudiante que no existe en el sistema. Entonces el sistema debe mostrar un error indicando que el estudiante no fue encontrado. | G18: X
A19: CA3 | B19: Dado que un Entrenador está creando un nuevo entrenamiento. Cuando intenta incluir una variable cognitiva que no existe o que está marcada como inactiva en el sistema. Entonces el sistema debe rechazar la creación y notificar al entrenador que una o más de las variables seleccionadas no son válidas. | G19: X
A20: CA4 | B20: Dado que un Entrenador está creando un nuevo entrenamiento para un estudiante. Cuando intenta guardar el entrenamiento sin haber seleccionado al menos una variable cognitiva. Entonces el sistema debe mostrar un mensaje de error indicando que se requiere seleccionar como mínimo una variable. | G20: X
A21: CA5 | B21: Dado que un Entrenador está en la interfaz para crear un nuevo entrenamiento. Cuando necesita seleccionar las variables cognitivas. Entonces el sistema debe presentarle únicamente la lista de variables que se encuentran "Activas" en el sistema. | G21: X

Sheet HU-BASE-004
A1: <-Volver al listado
A2: Título
A3: =MapeoImpactosComandos!J7 -> HU-BASE-004-Generar informes de entrenamientos cognitivos creados asignados
A4: Tarjeta
A5: Como | B5: =MapeoImpactosComandos!P7 -> Entrenador
A6: Necesito | B6: =MapeoImpactosComandos!Q7 -> poder generar informes de los entrenamientos cognitivos asignados
A7: Para | B7: =MapeoImpactosComandos!R7 -> Permitir la gestión de los estudiantes, dando el acceso a planes de entrenamiento, así como visualizar el progreso de los planes que desarrolle, lo que le concede la capacidad de medir su rendimiento en las diferentes planes de entrenamiento, ver el progreso del estudiante por medio de métricas, también visualizar el uso de la aplicación y la satisfacción de los estudiantes en el desarrollo del programa.
A8: =MapeoImpactosComandos!K7 -> Como Entrenador Necesito poder generar informes de los entrenamientos cognitivos asignados Para Permitir la gestión de los estudiantes, dando el acceso a planes de entrenamiento, así como visualizar el progreso de los planes que desarrolle, lo que le concede la capacidad de medir su rendimiento en las diferentes planes de entrenamiento, ver el progreso del estudiante por medio de métricas, también visualizar el uso de la aplicación y la satisfacción de los estudiantes en el desarrollo del programa.
A9: Tallaje
A10: =MapeoImpactosComandos!L3 -> Talla(Tamaño) | E10: =MapeoImpactosComandos!L7 -> M
A11: =MapeoImpactosComandos!M3 -> Talla(Complejidad) | E11: =MapeoImpactosComandos!M7 -> S
A12: ¿Definition of Ready? | E12: SI
A13: ¿Definition of Done? | E13: SI
A14: Criterios aceptación
A15: Código | B15: Escenario | G15: Estado | I15: Observación
G16: Aceptado | H16: No aceptado
A17: CA1 | B17: Dado que un entrenamiento cognitivo ha sido completado y su estado es "Finalizado". Cuando el Entrenador selecciona la opción "Generar informe final". Entonces el sistema debe generar un informe detallado que incluya las métricas finales de rendimiento, un resumen de todas las sesiones y las observaciones registradas. | G17: X
A18: CA2 | B18: Dado que se ha generado un informe (de progreso o final). Cuando el Entrenador lo visualiza. Entonces el informe debe incluir claramente los datos del estudiante y los datos del entrenador | G18: X
A19: CA3 | B19: Dado que un Entrenador necesita compartir un informe. Cuando genera un informe de progreso o final. Entonces el sistema debe ofrecer una opción para exportar o descargar dicho informe en un formato estándar (como XLSX). | G19: X

Sheet HU-BASE-005
A1: <-Volver al listado
A2: Título
A3: =MapeoImpactosComandos!J8 -> HU-BASE-005-Consultar historial de entrenamiento cognitivo
A4: Tarjeta
A5: Como | B5: =MapeoImpactosComandos!P8 -> Entrenador
A6: Necesito | B6: =MapeoImpactosComandos!Q8 -> poder consultar el historial de actividad de los diferentes entrenamientos cognitivos
A7: Para | B7: =MapeoImpactosComandos!R8 -> Permitir la gestión de los estudiantes, dando el acceso a planes de entrenamiento, así como visualizar el progreso de los planes que desarrolle, lo que le concede la capacidad de medir su rendimiento en las diferentes planes de entrenamiento, ver el progreso del estudiante por medio de métricas, también visualizar el uso de la aplicación y la satisfacción de los estudiantes en el desarrollo del programa.
A8: =MapeoImpactosComandos!K8 -> Como Entrenador Necesito poder consultar el historial de actividad de los diferentes entrenamientos cognitivos Para Permitir la gestión de los estudiantes, dando el acceso a planes de entrenamiento, así como visualizar el progreso de los planes que desarrolle, lo que le concede la capacidad de medir su rendimiento en las diferentes planes de entrenamiento, ver el progreso del estudiante por medio de métricas, también visualizar el uso de la aplicación y la satisfacción de los estudiantes en el desarrollo del programa.
A9: Tallaje
A10: =MapeoImpactosComandos!L3 -> Talla(Tamaño) | E10: =MapeoImpactosComandos!L8 -> XS
A11: =MapeoImpactosComandos!M3 -> Talla(Complejidad) | E11: =MapeoImpactosComandos!M8 -> S
A12: ¿Definition of Ready? | E12: SI
A13: ¿Definition of Done? | E13: SI
A14: Criterios aceptación
A15: Código | B15: Escenario | G15: Estado | I15: Observación
G16: Aceptado | H16: No aceptado
A17: CA1 | B17: Dado que un Entrenador está viendo el detalle de una variable cognitiva de un estudiante. Cuando selecciona la opción "Ver historial de sesiones". Entonces el sistema debe mostrarle una lista de todas las sesiones asociadas a esa variable. | G17: X
A18: CA2 | B18: Dado que un Entrenador está viendo el historial de sesiones. Cuando inspecciona una sesión de la lista. Entonces el sistema debe mostrar claramente el número de la sesión, su estado (ej: "Finalizado", "Por Iniciar"), la fecha de inicio, la fecha de fin y las observaciones registradas. | G18: X
A19: CA3 | B19: Dado que un Entrenador está revisando una variable cognitiva para la cual aún no se han creado sesiones. Cuando intenta consultar el historial. Entonces el sistema debe mostrar un mensaje claro indicando que "No existen sesiones programadas para esta variable". | G19: X
A20: CA4 | B20: Dado que un Administrador del sistema está autenticado. Cuando intenta registrar un nuevo entrenador asignándole una facultad que no existe en el sistema. Entonces el sistema debe rechazar la solicitud y mostrar un mensaje de error indicando que la facultad no es válida. | G20: X

Sheet HU-BASE-006
A1: <-Volver al listado
A2: Título
A3: =MapeoImpactosComandos!J9 -> HU-BASE-006-Crear un nuevo entrenamiento cognitivo
A4: Tarjeta
A5: Como | B5: =MapeoImpactosComandos!P9 -> Entrenador
A6: Necesito | B6: =MapeoImpactosComandos!Q9 -> poder crear un nuevo entrenamiento cognitivo
A7: Para | B7: =MapeoImpactosComandos!R9 -> Permitir la gestión de los estudiantes, dando el acceso a planes de entrenamiento, así como visualizar el progreso de los planes que desarrolle, lo que le concede la capacidad de medir su rendimiento en las diferentes planes de entrenamiento, ver el progreso del estudiante por medio de métricas, también visualizar el uso de la aplicación y la satisfacción de los estudiantes en el desarrollo del programa.
A8: =MapeoImpactosComandos!K9 -> Como Entrenador Necesito poder crear un nuevo entrenamiento cognitivo Para Permitir la gestión de los estudiantes, dando el acceso a planes de entrenamiento, así como visualizar el progreso de los planes que desarrolle, lo que le concede la capacidad de medir su rendimiento en las diferentes planes de entrenamiento, ver el progreso del estudiante por medio de métricas, también visualizar el uso de la aplicación y la satisfacción de los estudiantes en el desarrollo del programa.
A9: Tallaje
A10: =MapeoImpactosComandos!L3 -> Talla(Tamaño) | E10: =MapeoImpactosComandos!L9 -> S
A11: =MapeoImpactosComandos!M3 -> Talla(Complejidad) | E11: =MapeoImpactosComandos!M9 -> M
A12: ¿Definition of Ready? | E12: SI
A13: ¿Definition of Done? | E13: SI
A14: Criterios aceptación
A15: Código | B15: Escenario | G15: Estado | I15: Observación
G16: Aceptado | H16: No aceptado
A17: CA1 | B17: Dado que un Entrenador está en el formulario de creación de entrenamiento. Cuando intenta asignar el entrenamiento a un estudiante que no existe en el sistema. Entonces el sistema debe mostrar un error indicando que el estudiante no fue encontrado. | G17: X
A18: CA2 | B18: Dado que un Entrenador está creando un nuevo entrenamiento. Cuando intenta incluir una variable cognitiva que no existe o que está marcada como inactiva en el sistema. Entonces el sistema debe rechazar la creación y notificar al entrenador que una o más de las variables seleccionadas no son válidas. | G18: X
A19: CA3 | B19: Dado que un Entrenador está creando un nuevo entrenamiento para un estudiante. Cuando intenta guardar el entrenamiento sin haber seleccionado al menos una variable cognitiva. Entonces el sistema debe mostrar un mensaje de error indicando que se requiere seleccionar como mínimo una variable. | G19: X
A20: CA4 | B20: Dado que un Entrenador está en la interfaz para crear un nuevo entrenamiento. Cuando necesita seleccionar las variables cognitivas. Entonces el sistema debe presentarle únicamente la lista de variables que se encuentran "Activas" en el sistema. | G20: X
A21: CA5 | B21: Dado que un Entrenador está en la interfaz para crear un nuevo entrenamiento. Cuando necesita seleccionar una fecha de inicio. Entonces el sistema debe presentarle una forma de ingresar la fecha planteada para iniciar el entrenamiento. | G21: X

Sheet HU-BASE-007
A1: <-Volver al listado
A2: Título
A3: =MapeoImpactosComandos!J10 -> HU-BASE-007-Modificar un entrenamiento cognitivo
A4: Tarjeta
A5: Como | B5: =MapeoImpactosComandos!P10 -> Entrenador
A6: Necesito | B6: =MapeoImpactosComandos!Q10 -> poder editar un entrenamiento cognitivo
A7: Para | B7: =MapeoImpactosComandos!R10 -> Permitir la gestión de los estudiantes, dando el acceso a planes de entrenamiento, así como visualizar el progreso de los planes que desarrolle, lo que le concede la capacidad de medir su rendimiento en las diferentes planes de entrenamiento, ver el progreso del estudiante por medio de métricas, también visualizar el uso de la aplicación y la satisfacción de los estudiantes en el desarrollo del programa.
A8: =MapeoImpactosComandos!K10 -> Como Entrenador Necesito poder editar un entrenamiento cognitivo Para Permitir la gestión de los estudiantes, dando el acceso a planes de entrenamiento, así como visualizar el progreso de los planes que desarrolle, lo que le concede la capacidad de medir su rendimiento en las diferentes planes de entrenamiento, ver el progreso del estudiante por medio de métricas, también visualizar el uso de la aplicación y la satisfacción de los estudiantes en el desarrollo del programa.
A9: Tallaje
A10: =MapeoImpactosComandos!L3 -> Talla(Tamaño) | E10: =MapeoImpactosComandos!L10 -> S
A11: =MapeoImpactosComandos!M3 -> Talla(Complejidad) | E11: =MapeoImpactosComandos!M10 -> M
A12: ¿Definition of Ready? | E12: SI
A13: ¿Definition of Done? | E13: SI
A14: Criterios aceptación
A15: Código | B15: Escenario | G15: Estado | I15: Observación
G16: Aceptado | H16: No aceptado
A17: CA1 | B17: Dado que un Entrenador está viendo el detalle de un entrenamiento que está "En Progreso" o "Por Iniciar". Cuando selecciona la opción de añadir una nueva variable cognitiva válida. Entonces el sistema debe agregar esa variable al plan del estudiante en estado "Por Iniciar", sin afectar las demás. | G17: X
A18: CA2 | B18: Dado que un Entrenador está editando un entrenamiento. Cuando intenta quitar una variable cognitiva que aún se encuentra en estado "Por Iniciar". Entonces el sistema debe eliminarla del plan de entrenamiento del estudiante. | G18: X
A19: CA3 | B19: Dado que un Entrenador está gestionando un entrenamiento que ya tiene el estado "Finalizado" o "Abandono". Cuando intenta añadir o quitar una variable cognitiva. Entonces el sistema debe impedir la acción y mostrar un mensaje indicando que el entrenamiento no se puede modificar porque ya ha concluido. | G19: X
A20: CA4 | B20: Dado que un Entrenador está editando un entrenamiento que solo tiene una variable cognitiva asignada. Cuando intenta quitar esa última variable. Entonces el sistema debe rechazar la acción y mostrar un error que indique que el entrenamiento no puede quedar sin variables. | G20: X
A21: CA5 | B21: Dado que un Entrenador está editando un entrenamiento. Cuando intenta quitar una variable cognitiva cuyo estado ya es "Finalizado". Entonces el sistema debe impedir la acción y mostrar un mensaje que indique que las variables ya completadas no se pueden eliminar. | G21: X

Sheet HU-BASE-008
A1: <-Volver al listado
A2: Título
A3: =MapeoImpactosComandos!J11 -> HU-BASE-008-Iniciar sesion de entrenamiento
A4: Tarjeta
A5: Como | B5: =MapeoImpactosComandos!P11 -> Entrenador
A6: Necesito | B6: =MapeoImpactosComandos!Q11 -> poder iniciar una nueva sesión de entrenamiento inmediatamente
A7: Para | B7: =MapeoImpactosComandos!R11 -> Permitir la gestión de los estudiantes, dando el acceso a planes de entrenamiento, así como visualizar el progreso de los planes que desarrolle, lo que le concede la capacidad de medir su rendimiento en las diferentes planes de entrenamiento, ver el progreso del estudiante por medio de métricas, también visualizar el uso de la aplicación y la satisfacción de los estudiantes en el desarrollo del programa.
A8: =MapeoImpactosComandos!K11 -> Como Entrenador Necesito poder iniciar una nueva sesión de entrenamiento inmediatamente Para Permitir la gestión de los estudiantes, dando el acceso a planes de entrenamiento, así como visualizar el progreso de los planes que desarrolle, lo que le concede la capacidad de medir su rendimiento en las diferentes planes de entrenamiento, ver el progreso del estudiante por medio de métricas, también visualizar el uso de la aplicación y la satisfacción de los estudiantes en el desarrollo del programa.
A9: Nota: Por acuerdo con el Product Owner, el alcance de esta historia se simplificó. En lugar de programar sesiones a futuro, el Entrenador iniciará las sesiones de forma inmediata a través de un botón de 'play' para agilizar el desarrollo.
A10: Tallaje
A11: =MapeoImpactosComandos!L3 -> Talla(Tamaño) | E11: =MapeoImpactosComandos!L11 -> S
A12: =MapeoImpactosComandos!M3 -> Talla(Complejidad) | E12: =MapeoImpactosComandos!M11 -> S
A13: ¿Definition of Ready? | E13: SI
A14: ¿Definition of Done? | E14: SI
A15: Criterios aceptación
A16: Código | B16: Escenario | G16: Estado | I16: Observación
G17: Aceptado | H17: No aceptado
A18: CA1 | B18: Dado que un Entrenador está viendo una variable cognitiva que está "En Progreso" para un estudiante. Cuando presiona el botón "Iniciar nueva sesión". Entonces el sistema debe crear una nueva sesión con la fecha y hora actual, ponerla en estado "En Progreso" y permitir que el estudiante comience las actividades. | G18: X
A19: CA2 | B19: Dado que una variable cognitiva ya ha sido marcada como "Finalizada" o "Abandono". Cuando el Entrenador visualiza esa variable. Entonces el botón para "Iniciar nueva sesión" no debe estar visible o debe aparecer deshabilitado. | G19: X
A20: CA3 | B20: Dado que un Entrenador inicia una nueva sesión. Cuando el sistema crea el nuevo registro de sesión. Entonces el número de sesión asignado debe ser secuencial y corresponder al siguiente número para esa variable cognitiva (ej. si ya existían 3 sesiones, esta debe ser la número 4). | G20: X

Sheet HU-BASE-009
A1: <-Volver al listado
A2: Título
A3: =MapeoImpactosComandos!J12 -> HU-BASE-009-Ingresar a una variable cognitiva a la que tenga acceso
A4: Tarjeta
A5: Como | B5: =MapeoImpactosComandos!P12 -> Estudiante
A6: Necesito | B6: =MapeoImpactosComandos!Q12 -> poder ingresar a una variable cognitiva a la que tenga acceso
A7: Para | B7: =MapeoImpactosComandos!R12 -> Realizar los diferentes entrenamientos cognitivos asignados, con el fin de mejorar las habilidades cognitivas en las que se haya identificado una oportunidad de desarrollo en el estudiante. ​
A8: =MapeoImpactosComandos!K12 -> Como Estudiante Necesito poder ingresar a una variable cognitiva a la que tenga acceso Para Realizar los diferentes entrenamientos cognitivos asignados, con el fin de mejorar las habilidades cognitivas en las que se haya identificado una oportunidad de desarrollo en el estudiante. ​
A9: Tallaje
A10: =MapeoImpactosComandos!L3 -> Talla(Tamaño) | E10: =MapeoImpactosComandos!L12 -> S
A11: =MapeoImpactosComandos!M3 -> Talla(Complejidad) | E11: =MapeoImpactosComandos!M12 -> S
A12: ¿Definition of Ready? | E12: SI
A13: ¿Definition of Done? | E13: SI
A14: Criterios aceptación
A15: Código | B15: Escenario | G15: Estado | I15: Observación
G16: Aceptado | H16: No aceptado
A17: CA1 | B17: Dado que un Estudiante está viendo su lista de entrenamientos. Cuando selecciona una variable cognitiva que tiene asignada. Entonces el sistema debe mostrarle una pantalla de detalle para esa variable, con su nombre, descripción, y la lista de sus sesiones de entrenamiento. | G17: X
A18: CA2 | B18: Dado que un Estudiante está en la pantalla de detalle de una variable. Cuando revisa la lista de sesiones. Entonces el sistema debe diferenciar visualmente el estado de cada sesión (ej: 'Completada', 'Pendiente', 'En Curso'). | G18: X
A19: CA3 | B19: Dado que un Estudiante intenta acceder a una variable cognitiva que no le ha sido asignada (por ejemplo, a través de una URL directa). Cuando realiza la solicitud. Entonces el sistema debe denegarle el acceso y mostrar un error de permisos o de "no encontrado". | G19: X

Sheet HU-BASE-010
A1: <-Volver al listado
A2: Título
A3: =MapeoImpactosComandos!J13 -> HU-BASE-010-Abandonar variable cognitiva
A4: Tarjeta
A5: Como | B5: =MapeoImpactosComandos!P13 -> Estudiante
A6: Necesito | B6: =MapeoImpactosComandos!Q13 -> poder abandonar el entrenamiento cognitivo que esté desarrollando
A7: Para | B7: =MapeoImpactosComandos!R13 -> Realizar los diferentes entrenamientos cognitivos asignados, con el fin de mejorar las habilidades cognitivas en las que se haya identificado una oportunidad de desarrollo en el estudiante. ​
A8: =MapeoImpactosComandos!K13 -> Como Estudiante Necesito poder abandonar el entrenamiento cognitivo que esté desarrollando Para Realizar los diferentes entrenamientos cognitivos asignados, con el fin de mejorar las habilidades cognitivas en las que se haya identificado una oportunidad de desarrollo en el estudiante. ​
A9: Tallaje
A10: =MapeoImpactosComandos!L3 -> Talla(Tamaño) | E10: =MapeoImpactosComandos!L13 -> XS
A11: =MapeoImpactosComandos!M3 -> Talla(Complejidad) | E11: =MapeoImpactosComandos!M13 -> XS
A12: ¿Definition of Ready? | E12: SI
A13: ¿Definition of Done? | E13: SI
A14: Criterios aceptación
A15: Código | B15: Escenario | G15: Estado | I15: Observación
G16: Aceptado | H16: No aceptado
A17: CA1 | B17: Dado que un Estudiante está viendo una variable cognitiva que se encuentra "En Progreso". Cuando selecciona la opción para "Abandonar variable" y confirma su decisión. Entonces el sistema debe cambiar el estado de esa variable a "Abandono" y ya no podrá iniciar nuevas sesiones para ella. | G17: X
A18: CA2 | B18: Dado que un Estudiante abandona la última variable que le quedaba en su entrenamiento. Cuando la variable es marcada como "Abandono". Entonces el sistema debe actualizar el estado del entrenamiento cognitivo general a "Abandono". | G18: X
A19: CA3 | B19: Dado que un Estudiante está viendo una variable cognitiva que ya completó (estado "Finalizado"). Cuando busca la opción para abandonarla. Entonces el sistema no le debe permitir abandonar | G19: X

Sheet HU-BASE-011
A1: <-Volver al listado
A2: Título
A3: =MapeoImpactosComandos!J14 -> HU-BASE-011-Registrar un nuevo estudiante
A4: Tarjeta
A5: Como | B5: =MapeoImpactosComandos!P14 -> Entrenador
A6: Necesito | B6: =MapeoImpactosComandos!Q14 -> poder registrar a un nuevo estudiante remitido por pedagogos
A7: Para | B7: =MapeoImpactosComandos!R14 -> Permitir la gestión de los estudiantes, dando el acceso a planes de entrenamiento, así como visualizar el progreso de los planes que desarrolle, lo que le concede la capacidad de medir su rendimiento en las diferentes planes de entrenamiento, ver el progreso del estudiante por medio de métricas, también visualizar el uso de la aplicación y la satisfacción de los estudiantes en el desarrollo del programa.
A8: =MapeoImpactosComandos!K14 -> Como Entrenador Necesito poder registrar a un nuevo estudiante remitido por pedagogos Para Permitir la gestión de los estudiantes, dando el acceso a planes de entrenamiento, así como visualizar el progreso de los planes que desarrolle, lo que le concede la capacidad de medir su rendimiento en las diferentes planes de entrenamiento, ver el progreso del estudiante por medio de métricas, también visualizar el uso de la aplicación y la satisfacción de los estudiantes en el desarrollo del programa.
A9: Tallaje
A10: =MapeoImpactosComandos!L3 -> Talla(Tamaño) | E10: =MapeoImpactosComandos!L14 -> S
A11: =MapeoImpactosComandos!M3 -> Talla(Complejidad) | E11: =MapeoImpactosComandos!M14 -> S
A12: ¿Definition of Ready? | E12: SI
A13: ¿Definition of Done? | E13: SI
A14: Criterios aceptación
A15: Código | B15: Escenario | G15: Estado | I15: Observación
G16: Aceptado | H16: No aceptado
A17: CA1 | B17: Dado que un Entrenador está registrando un nuevo estudiante. Cuando ingresa un tipo y número de documento que ya existen en el sistema. Entonces el sistema debe rechazar la solicitud y mostrar un error indicando que el estudiante ya se encuentra registrado. | G17: X
A18: CA2 | B18: Dado que un Entrenador está registrando un nuevo estudiante. Cuando ingresa una dirección de correo electrónico que ya está en uso. Entonces el sistema debe rechazar la solicitud y mostrar un error indicando que el correo electrónico ya está registrado. | G18: X
A19: CA3 | B19: Dado que un Entrenador está registrando un nuevo estudiante. Cuando intenta registrarlo sin asignarle al menos un programa académico. Entonces el sistema debe mostrar un error indicando que se debe seleccionar como mínimo un programa. | G19: X
A20: CA4 | B20: Dado que un Entrenador está registrando un nuevo estudiante. Cuando selecciona un programa académico que no es válido o no existe en la lista de programas. Entonces el sistema debe rechazar el registro y mostrar un error que indique que el programa no es válido. | G20: X

Sheet HU-BASE-012
A1: <-Volver al listado
A2: Título
A3: =MapeoImpactosComandos!J15 -> HU-BASE-012-Aprobar abandono de variable cognitiva del estudiante
A4: Tarjeta
A5: Como | B5: =MapeoImpactosComandos!P15 -> Entrenador
A6: Necesito | B6: =MapeoImpactosComandos!Q15 -> poder aprobar el abandono de un estudiante
A7: Para | B7: =MapeoImpactosComandos!R15 -> Permitir la gestión de los estudiantes, dando el acceso a planes de entrenamiento, así como visualizar el progreso de los planes que desarrolle, lo que le concede la capacidad de medir su rendimiento en las diferentes planes de entrenamiento, ver el progreso del estudiante por medio de métricas, también visualizar el uso de la aplicación y la satisfacción de los estudiantes en el desarrollo del programa.
A8: =MapeoImpactosComandos!K15 -> Como Entrenador Necesito poder aprobar el abandono de un estudiante Para Permitir la gestión de los estudiantes, dando el acceso a planes de entrenamiento, así como visualizar el progreso de los planes que desarrolle, lo que le concede la capacidad de medir su rendimiento en las diferentes planes de entrenamiento, ver el progreso del estudiante por medio de métricas, también visualizar el uso de la aplicación y la satisfacción de los estudiantes en el desarrollo del programa.
A9: Tallaje
A10: =MapeoImpactosComandos!L3 -> Talla(Tamaño) | E10: =MapeoImpactosComandos!L15 -> XS
A11: =MapeoImpactosComandos!M3 -> Talla(Complejidad) | E11: =MapeoImpactosComandos!M15 -> XS
A12: ¿Definition of Ready? | E12: SI
A13: ¿Definition of Done? | E13: SI
A14: Criterios aceptación
A15: Código | B15: Escenario | G15: Estado | I15: Observación
G16: Aceptado | H16: No aceptado
A17: CA1 | B17: Dado que un Entrenador está viendo una variable cognitiva "En Progreso" de un estudiante. Cuando selecciona la opción "Abandonar" para esa variable. Entonces el sistema debe cambiar el estado de la variable a "Abandono", y ya no se podrán iniciar nuevas sesiones para ella. | G17: X
A18: CA2 | B18: Dado que un Entrenador abandona la última variable que le quedaba activa a un estudiante en su entrenamiento. Cuando la variable es marcada como "Abandono". Entonces el sistema debe actualizar también el estado del entrenamiento cognitivo general a "Abandono". | G18: X
A19: CA3 | B19: Dado que un Entrenador está viendo una variable que el estudiante ya completó . Cuando busca la opción para marcarla como abandono. Entonces dicha no le debe permitir marcar la variable como abandono | G19: X

Sheet HU-BASE-013
A1: <-Volver al listado
A2: Título
A3: =MapeoImpactosComandos!J16 -> HU-BASE-013-Generar informes de entrenamientos cognitivos creados
A4: Tarjeta
A5: Como | B5: =MapeoImpactosComandos!P16 -> Administrador del sistema
A6: Necesito | B6: =MapeoImpactosComandos!Q16 -> poder generar informes de los entrenamientos cognitivos
A7: Para | B7: =MapeoImpactosComandos!R16 -> Permitir la gestión de los entrenadores e informes generados por la aplicación, para facilitar la supervisión y el seguimiento de los procesos.
A8: =MapeoImpactosComandos!K16 -> Como Administrador del sistema Necesito poder generar informes de los entrenamientos cognitivos Para Permitir la gestión de los entrenadores e informes generados por la aplicación, para facilitar la supervisión y el seguimiento de los procesos.
A9: Tallaje
A10: =MapeoImpactosComandos!L3 -> Talla(Tamaño) | E10: =MapeoImpactosComandos!L16 -> M
A11: =MapeoImpactosComandos!M3 -> Talla(Complejidad) | E11: =MapeoImpactosComandos!M16 -> S
A12: ¿Definition of Ready? | E12: SI
A13: ¿Definition of Done? | E13: SI
A14: Criterios aceptación
A15: Código | B15: Escenario | G15: Estado | I15: Observación
G16: Aceptado | H16: No aceptado
A17: CA1 | B17: Dado que un Administrador del sistema está autenticado. Cuando accede a la sección de informes. Entonces el sistema debe mostrarle una lista de todos los entrenamientos cognitivos existentes. | G17: X
A18: CA2 | B18: Dado que un Administrador ha seleccionado un entrenamiento específico de la lista global. Cuando presiona la opción "Generar Informe". Entonces el sistema debe generar un informe detallado para ese entrenamiento, sin importar a qué entrenador pertenezca. | G18: X
A19: CA3 | B19: Dado que un Administrador genera un informe. Cuando lo visualiza. Entonces el informe debe contener los datos completos del estudiante, los datos del entrenador asignado, el estado de cada variable cognitiva y las métricas de rendimiento. | G19: X
A20: CA4 | B20: Dado que un usuario que no es Administrador (ej. un Entrenador) intenta acceder a la URL del panel de informes global. Cuando realiza la solicitud. Entonces el sistema debe denegarle el acceso. | G20: X

Sheet HU-BASE-014
A1: <-Volver al listado
A2: Título
A3: =MapeoImpactosComandos!J17 -> HU-BASE-014-Crear observación de sesión de entrenamiento
A4: Tarjeta
A5: Como | B5: =MapeoImpactosComandos!P17 -> Entrenador
A6: Necesito | B6: =MapeoImpactosComandos!Q17 -> poder generar comentarios sobre la sesión de un estudiante en su entrenamiento cognitivo
A7: Para | B7: =MapeoImpactosComandos!R17 -> Permitir la gestión de los estudiantes, dando el acceso a planes de entrenamiento, así como visualizar el progreso de los planes que desarrolle, lo que le concede la capacidad de medir su rendimiento en las diferentes planes de entrenamiento, ver el progreso del estudiante por medio de métricas, también visualizar el uso de la aplicación y la satisfacción de los estudiantes en el desarrollo del programa.
