Workbook

Sheet Modelo dominio anémico contexto

Sheet Valores
A1: Tipo Objeto Dominio
A2: Tipo | B2: Descripción
A3: Propio | B3: Cuando el objeto de dominio es parte del contexto actual
A4: Referenciado | B4: Cuando el objeto de dominio es parte de otro contexto
A5: Aplica | B5: Cuando el atributo se usa para una función
A6: No aplica | B6: Cuando el atributo no se usa para una función
A7: Filtra/No mostrar | B7: Cuando el atributo ayuda en la consulta de un objeto de dominio y el dato se muestra
A8: Filtra/Mostrar | B8: Cuando el atributo ayuda en la consulta de un objeto de dominio, pero el dato no se muestra
A9: Si | B9: Afirmación en las cateréticas de un atributo
A10: No | B10: Negación en las cateréticas de un atributo
A11: Componente Centralizador | B11: =_xlfn.CONCAT("Contexto perteneciente al ", A11) -> Contexto perteneciente al Componente Centralizador
A12: Lectura Crítica | B12: =_xlfn.CONCAT("Contexto perteneciente a ", A12) -> Contexto perteneciente a Lectura Crítica
A13: Procrastinación | B13: =_xlfn.CONCAT("Contexto perteneciente a ", A13) -> Contexto perteneciente a Procrastinación
A14: Control Inhibitorio | B14: =_xlfn.CONCAT("Contexto perteneciente a ", A14) -> Contexto perteneciente a Control Inhibitorio
A15: Razonamiento Cuantitativo | B15: =_xlfn.CONCAT("Contexto perteneciente a ", A15) -> Contexto perteneciente a Razonamiento Cuantitativo

Sheet Listado Objetos de Dominio
A1: Subdominio/Contexto:
A2: Nombre | B2: Descripción | C2: Tipo | D2: Contexto
A3: Estudiante | B3: Objeto de dominio correspondiente a los estudiantes registrados en la aplicación Cognicare. | C3: Propio | D3: Componente Centralizador
A4: Entrenador | B4: Objeto de dominio correspondiente a los entrenadores de la aplicación Cognicare | C4: Propio | D4: Componente Centralizador
A5: Administrador | B5: Objeto de dominio correspondiente a los administrador de la aplicación Cognicare | C5: Propio | D5: Componente Centralizador
A6: Estudiante Programa | B6: Objeto de dominio que contiene a los programas por estudiante | C6: Propio | D6: Componente Centralizador
A7: Entrenador Facultad | B7: Objeto de dominio que contiene a los entrenadores por facultad | C7: Propio | D7: Componente Centralizador
A8: Entrenador Entrenamiento | B8: Objeto de dominio que corresponde a la tabla intermedia de la relación de muchos a muchos entre entrenador y entrenamiento cognitivo | C8: Propio | D8: Componente Centralizador
A9: Entrenamiento Cognitivo | B9: Objeto de dominio encargado de contener el plan de entrenamiento que desarrolla el estudiante | C9: Propio | D9: Componente Centralizador
A10: Sesion Entrenamiento | B10: Objeto de dominio que contiene las sesiones de entrenamiento creadas | C10: Propio | D10: Componente Centralizador
A11: Asignación Variable | B11: Objeto de dominio el cual anuncia el estado de las diferentes variables cognitivas a las que el estudiante tiene acceso | C11: Propio | D11: Componente Centralizador
A12: Variable Cognitiva | B12: Objeto de dominio que contiene las diferentes variables cognitivas de la aplicacion | C12: Propio | D12: Componente Centralizador
A13: Tipo Documento | B13: Objeto de dominio que contiene los diferentes documentos de identidad válidos | C13: Propio | D13: Componente Centralizador
... A17: Genero | B17: Objeto que contiene el género | C17: Propio | D17: Componente Centralizador

Sheet Estudiante
A1: <-Volver al inicio
A2: Objeto de Dominio: | B2: ='Listado Objetos de Dominio'!$A$3 -> Estudiante
A3: Descripción: | B3: ='Listado Objetos de Dominio'!$B$3 -> Objeto de dominio correspondiente a los estudiantes registrados en la aplicación Cognicare.
A4: Atributo | B4: Tipo de Dato | C4: Longitud mínima | D4: Longitud máxima | E4: Precisión | F4: Rango Inicial | G4: Rango Final | H4: Formato | I4: Valor por defecto | J4: Regla especial | K4: ¿Auto generado? | L4: ¿Calculado? | M4: ¿Obligatorio? | N4: ¿Sensible? | O4: ¿Identifica al registro? | P4: Descripción | Q4: =A22 -> Registrar Estudiante | R4: =A31 -> Modificar Informacion de Estudiante | S4: =A39 -> Consultar Estudiante | T4: =A41 -> Actualizar Genero Estudiante
A5: identificador | B5: UUID | C5: 36 | D5: 36 | H5: Formato de un identificador único universal (UUID) | K5: Si | L5: No | M5: Si | N5: Si | O5: Si | P5: Es el valor único para identificar el registro del estudiante ingresado en Cognicare | Q5: Aplica | R5: No aplica | S5: No aplica | T5: No aplica
A6: nombre | B6: String | C6: 1 | D6: 200 | H6: Solo letras y espacios | K6: No | L6: No | M6: Si | N6: No | O6: No | P6: Nombre del estudiante | Q6: Aplica | R6: Aplica | S6: Filtra/Mostrar | T6: No aplica
A7: Apellido | B7: String | C7: 1 | D7: 200 | H7: Solo letras y espacios | K7: No | L7: No | M7: Si | N7: No | O7: No | P7: Apellidos del estudiante | Q7: Aplica | R7: Aplica | S7: Filtra/Mostrar | T7: No aplica
A8: tipoDocumento | B8: UUID | H8: Formato de un identificador único universal (UUID) | K8: No | L8: No | M8: Si | N8: No | O8: No | P8: Programa al que pertenece el estudiante | Q8: Aplica | R8: No aplica | S8: Filtra/Mostrar | T8: No aplica
A9: numeroDocumento | B9: String | C9: 1 | D9: 20 | H9: Solo números | K9: No | L9: No | M9: Si | N9: No | O9: No | P9: Número de documento identificador del estudiante | Q9: Aplica | R9: No aplica | S9: Filtra/Mostrar | T9: No aplica
A10: genero | B10: UUID | H10: Formato de un identificador único universal (UUID) | K10: No | L10: No | M10: Si | N10: No | O10: No | P10: Género que selecciona el estudiante al ingresar por primera vez a Cognicare | Q10: Aplica | R10: Aplica | S10: Filtra/Mostrar | T10: Aplica
A11: fechaNacimiento | B11: Date | H11: YYYY-MM-DD | K11: No | L11: No | M11: Si | N11: No | O11: No | P11: Fecha de nacimiento del estudiante | Q11: Aplica | R11: Aplica | S11: Filtra/Mostrar | T11: No aplica
A12: correo | B12: String | C12: 1 | D12: 300 | H12: ^[a-zA-Z0-9._%+-]+@[a-zA-Z0-9.-]+\.[a-zA-Z]{2,}$ | K12: No | L12: No | M12: Si | N12: Si | O12: Si | P12: Correo electronico del estudiante | Q12: Aplica | R12: Aplica | S12: Filtra/Mostrar | T12: No aplica
A14: Combinaciones únicas
A15: Nombre combinación | B15: Descripción | C15: Atributos
A16: Combinación 1 | B16: No es posible que dos o más estudiantes tengan el mismo tipo y número de documento | C16: tipoDocumento
C17: numeroDocumento
A18: Combinación 2 | B18: No es posible que dos o más estudiantes tengan el mismo correo | C18: =A12 -> correo
A20: Responsabilidad | C20: Descripción | G20: Entradas | J20: Salida | O20: Políticas (Reglas de Negocio)
G21: Parámetro | H21: Tipo de dato | I21: Descripción | J21: Tipo de Dato | K21: Descripción | O21: Política | P21: Descripción | Q21: Detalle | R21: ¿Qué hago?
A22: Registrar Estudiante | C22: Crea un nuevo estudiante en el sistema, asociándolo a sus datos personales y a uno o más programas académicos. | G22: siglaTipoDocumento | H22: String | I22: Sigla del tipo de documento (ej: "CC"). | J22: Object | K22: JSON Confirmando el exito del registro | O22: RN-Estudiante-01 | P22: La combinacion de Numero y Tipo de documento debe ser unica | Q22: Tipo de documento y numero ya existen | R22: Retornar Error 409 (conflict)
G23: nombreGenero | H23: String | I23: Nombre del género del estudiante.
G24: nombres | H24: String | I24: Nombres del estudiante. | O24: RN-Estudiante-02 | P24: El estudiante debe inscribirse en al menos un programa y máximo dos | Q24: Número de programas inválido | R24: Mostrar mensaje de error
G25: apellidos | H25: String | I25: Apellidos del estudiante.
G26: numeroDocumento | H26: String | I26: Número de documento del estudiante. | O26: RN-Estudiante-03 | P26: La fecha de nacimiento no puede ser una fecha futura | Q26: Datos de entrada inválidos | R26: Mostrar mensaje de error con la validación
G27: fechaNacimiento | H27: Date | I27: Fecha de nacimiento en formato YYYY-MM-DD.
G28: correo | H28: String | I28: Correo electrónico del estudiante. | O28: RN-Estudiante-04 | P28: El formato del correo electrónico debe ser válido. | Q28: Datos de entrada inválidos | R28: Mostrar mensaje de error con la validación
G29: programaNombres | H29: Array<String> | I29: Lista de nombres de los programas.
O30: RN-Estudiante-05 | P30: Los datos no pueden estar vacíos | Q30: Datos de entrada inválidos | R30: Mostrar mensaje de error con la validación
A31: Modificar Informacion de Estudiante | C31: Actualiza los datos personales y/o los programas académicos de un estudiante existente. | G31: siglaTipoDocumento | H31: String | I31: Sigla del tipo de documento (ej: "CC"). | J31: Object | K31: JSON Confirmando el exito del registro | O31: RN-Estudiante-05 | P31: El correo, si se modifica, debe seguir siendo único entre todos los estudiantes. | Q31: Correo ya existente | R31: Retornar Error 409 (conflict)
G32: nombreGenero | H32: String | I32: Nombre del género del estudiante.
G33: nombres | H33: String | I33: Nombres del estudiante.
G34: apellidos | H34: String | I34: Apellidos del estudiante.
G35: numeroDocumento | H35: String | I35: Número de documento del estudiante. | O35: RN-Estudiante-06 | P35: Si se modifica la lista de programas, debe contener entre 1 y 2 programas | Q35: Número de programas inválido | R35: Mostrar mensaje de error
G36: fechaNacimiento | H36: Fecha | I36: Fecha de nacimiento en formato YYYY-MM-DD.
G37: correo | H37: String | I37: Correo electrónico del estudiante.
G38: programaNombres | H38: Array<String> | I38: Lista de nombres de los programas.
A39: Consultar Estudiante | C39: Obtiene la información completa y detallada de un estudiante, incluyendo sus programas académicos | G39: SiglaTipoDocumento | H39: String | I39: Sigla del tipo de documento (ej: "CC"). | J39: Object | K39: JSON con los datos del estudiante | O39: RN-Estudiante-07 | P39: La consulta devuelve un único registro de estudiante o ninguno. | Q39: Estudiante no encontrado | R39: Retornar un error 404 y el mensaje
G40: numeroDocumento | H40: String | I40: Número de documento del estudiante.
A41: Actualizar Genero Estudiante | C41: Modifica únicamente el campo de género de un estudiante existente, identificado por su UUID. | G41: id | H41: UUID | I41: ID único del estudiante. | J41: Object | K41: Objeto JSON que confirma la actualización.

Sheet Entrenador
A1: <-Volver al inicio
A2: Objeto de Dominio: | B2: ='Listado Objetos de Dominio'!$A$4 -> Entrenador
A3: Descripción: | B3: ='Listado Objetos de Dominio'!$B$4 -> Objeto de dominio correspondiente a los entrenadores de la aplicación Cognicare
A4: Atributo | B4: Tipo de Dato | C4: Longitud mínima | D4: Longitud máxima | E4: Precisión | F4: Rango Inicial | G4: Rango Final | H4: Formato | I4: Valor por defecto | J4: Regla especial | K4: ¿Auto generado? | L4: ¿Calculado? | M4: ¿Obligatorio? | N4: ¿Sensible? | O4: ¿Identifica al registro? | P4: Descripción | Q4: =A22 -> Registrar Nuevo Entrenador | R4: =A29 -> Modificar Información | S4: =A35 -> Desactivar Entrenador | T4: =A38 -> Listar Entrenadores | U4: =A40 -> Autenticar Entrenador | V4: =A43 -> Asignar a Entrenamiento
A5: identificador | B5: UUID | C5: 36 | D5: 36 | H5: Formato de un identificador único universal (UUID) | K5: Si | L5: No | M5: Si | N5: Si | O5: Si | P5: Valor único para identificar el registro del entrenador en Cognicare | Q5: Aplica | R5: No aplica | S5: No aplica | T5: Filtra/No mostrar | U5: No aplica | V5: No aplica
A6: nombre | B6: String | C6: 1 | D6: 200 | H6: Solo letras y espacios | K6: No | L6: No | M6: Si | N6: No | O6: No | P6: Nombre del entrenador | Q6: Aplica | R6: Aplica | S6: No aplica | T6: Filtra/Mostrar | U6: No aplica | V6: No aplica
A7: apellido | B7: String | C7: 1 | D7: 200 | H7: Solo letras y espacios | K7: No | L7: No | M7: Si | N7: No | O7: No | P7: Apellidos del entrenador | Q7: Aplica | R7: Aplica | S7: No aplica | T7: Filtra/Mostrar | U7: No aplica | V7: No aplica
A8: tipoDocumento | B8: UUID | H8: Formato de un identificador único universal (UUID) | K8: No | L8: No | M8: Si | N8: No | O8: No | P8: Atributo que permite identificar el tipo de documento que tiene un estudiante, sea de cedula o tarjeta de identidad | Q8: Aplica | R8: No aplica | S8: No aplica | T8: Filtra/Mostrar | U8: Aplica | V8: No aplica
A9: numeroDocumento | B9: String | C9: 1 | D9: 20 | H9: Solo números | K9: No | L9: No | M9: Si | N9: No | O9: No | P9: Número de documento identificador del entrenador | Q9: Aplica | R9: No aplica | S9: No aplica | T9: Filtra/Mostrar | U9: Aplica | V9: No aplica
A10: fechaInicio | B10: Date | H10: YYYY-MM-DD | I10: Fecha Actual | K10: Si | L10: No | M10: Si | N10: No | O10: No | P10: Fecha de inicio de actividad del entrenador en Cognicare | Q10: Aplica | R10: No aplica | S10: No aplica | T10: Filtra/No mostrar | U10: No aplica | V10: No aplica
A11: fechaFinal | B11: Date | H11: YYYY-MM-DD | I11: Fecha Actual + 6 meses | K11: No | L11: Si | M11: Si | N11: No | O11: No | P11: Fecha final de actividad del entrenador en Cognicare | Q11: Aplica | R11: Aplica | S11: Aplica | T11: Filtra/Mostrar | U11: No aplica | V11: No aplica
A12: correo | B12: String | C12: 1 | D12: 300 | H12: ^[a-zA-Z0-9._%+-]+@[a-zA-Z0-9.-]+\.[a-zA-Z]{2,}$ | K12: No | L12: No | M12: Si | N12: Si | O12: Si | Q12: Aplica | R12: Aplica | S12: No aplica | T12: Filtra/Mostrar | U12: No aplica | V12: No aplica
A14: Combinaciones únicas
A15: Nombre combinación | B15: Descripción | C15: Atributos
A16: Combinación 1 | B16: No es posible que dos o más entrenadores tengan el mismo tipo de documento y número de documento | C16: tipoDocumento
C17: numeroDocumento
A18: Combinación 2 | B18: No es posible que dos o más entrenadores tengan el mismo correo | C18: =A12 -> correo
A20: Responsabilidad | C20: Descripción | G20: Entradas | J20: Salida | O20: Políticas (Reglas de Negocio) | Q20: Excepción
G21: Parámetro | H21: Tipo de dato | I21: Descripción | J21: Tipo de Dato | K21: Descripción | O21: Política | P21: Descripción | Q21: Detalle | R21: ¿Qué hago?
A22: Registrar Nuevo Entrenador | C22: Crea un nuevo usuario con rol de Entrenador. Esta operación solo puede ser realizada por un Administrador. | G22: siglaTipoDocumento | H22: String | I22: Sigla del tipo de documento (ej: "CC"). | J22: Object | K22: Objeto JSON que confirma el éxito del registro. | O22: RN-Entrenador-01 | P22: La operación solo puede ser realizada por un usuario con rol de Admin. | Q22: Token inválido o sin rol de Admin | R22: No permitirrealizar el registro
G23: numeroDocumento | H23: String | I23: Número de documento del nuevo entrenador. | O23: RN-Entrenador-02 | P23: Tipo y número de documendo únicos | Q23: Tipo y numero de documento ya existente | R23: Mostrar un mensaje de error
G24: nombres | H24: String | I24: Nombres del entrenador. | O24: RN-Entrenador-03 | P24: Correo debe ser único | Q24: Correo ya existente | R24: Mostrar mensaje de error
G25: apellidos | H25: String | I25: Apellidos del entrenador. | O25: RN-Entrenador-04 | P25: Se debe asignar al menos una facultad al entrenador | Q25: Datos de entrada invalidos | R25: Mostrar mensaje de error
G26: correo | H26: String | I26: Correo electrónico del entrenador.
G27: facultadNombres | H27: Array<String> | I27: Lista de los nombres de las facultades a las que se asociará. | O27: RN-Entrenador-05 | P27: Los datos del entrenador no deben ser vacíos | Q27: Datos de entrada invalidos | R27: Mostrar mensaje de error
G28: fechaFin | H28: Date | I28: (Opcional) Fecha de finalización del contrato.
A29: Modificar Información | C29: Actualiza los datos personales y/o las facultades de un entrenador existente. Solo para Administradores. | G29: entrenadorId | H29: UUID | I29: ID único del entrenador a modificar. | J29: Object | K29: Objeto JSON que confirma el éxito de la actualización | O29: RN-Entrenador-01 | P29: La operación solo puede ser realizada por un usuario con rol de Admin. | Q29: Token inválido o sin rol de Admin | R29: No permitir realizar la actualización
G30: nuevosNombres | H30: String | I30: (Opcional) Nuevos nombres
G31: nuevosApellidos | H31: String | I31: (Opcional) Nuevos apellidos. | O31: RN-Entrenador-06 | P31: El correo, si se modifica, debe seguir siendo único. | Q31: Correo ya existente | R31: Mostrar mensaje de error
G32: nuevoCorreo | H32: String | I32: (Opcional) Nuevo correo. | Q32: Entrenador no encontrado | R32: Retornar un error 404 Not Found
G33: nuevaFechaFin | H33: Date | I33: (Opcional) Nueva fecha de fin de contrato. | O33: RN-Entrenador-07 | P33: La nueva lista de facultades reemplaza completamente a la anterior. | Q33: Datos de entrada inválidos | R33: Retornar un error 400 Bad Request.
G34: nuevosNombresFacultades | H34: Array<String> | I34: (Opcional) Lista completa que reemplaza las facultades anteriores. | Q34: Error inesperado del servidor | R34: Retornar un error 500 Internal Server Error
A35: Desactivar Entrenador | C35: Marca a un entrenador como inactivo, estableciendo su fecha de fin de contrato al día actual. Solo para Administradores. | G35: entrenadorID | H35: UUID | I35: ID único del entrenador a desactivar. | J35: Object | K35: Objeto JSON que confirma la desactivación. | O35: RN-Entrenador-08 | P35: La desactivación se logra actualizando el campo fechaFin a la fecha actual. | Q35: Entrenador no encontrado | R35: Retornar un error 404 Not Found
Q36: Error inesperado del servidor | R36: Retornar un error 500 Internal Server Error
Q37: Token inválido o sin rol de Admin | R37: Retornar un error 401 Unauthorized o 403 Forbidden.
A38: Listar Entrenadores | C38: Obtiene una lista de todos los entrenadores registrados en el sistema. Solo para Administradores. | G38: nombreFacultad | H38: String | I38: (Opcional) Filtra la lista por el nombre de una facultad. | J38: Object | K38: Objeto JSON que contiene la lista de entrenadores. | O38: RN-Entrenador-01 | P38: La operación solo puede ser realizada por un usuario con rol de Admin. | Q38: Token inválido o sin rol de Admin | R38: Retornar un error 401 Unauthorized o 403 Forbidden
Q39: Error inesperado del servidor | R39: Retornar un error 500 Internal Server Error
A40: Autenticar Entrenador | C40: alida las credenciales de un entrenador (correo y documento) y genera un token de acceso JWT. | G40: correo | H40: String | I40: Correo electrónico del entrenador. | J40: Object | K40: Objeto JSON que confirma el éxito de la autenticación | O40: RN-Entrenador-09 | P40: El entrenador debe existir, estar activo y las credenciales deben coincidir | Q40: Faltan datos | R40: Mostrar un mensaje con los datos faltantes
G41: numeroDocumento | H41: String | I41: Número de documento del entrenador, usado como credencial. | Q41: Credenciales inválidas o entrenador inactivo | R41: Mostrar un mensaje 401 Unauthorized
Q42: Error inesperado del servidor | R42: Retornar un error 500 Internal Server Error
...

Sheet Administrador
A1: <-Volver al inicio
A2: Objeto de Dominio: | B2: ='Listado Objetos de Dominio'!A5 -> Administrador
A3: Descripción: | B3: ='Listado Objetos de Dominio'!B5 -> Objeto de dominio correspondiente a los administrador de la aplicación Cognicare
A4: Atributo | B4: Tipo de Dato | C4: Longitud mínima | D4: Longitud máxima | E4: Precisión | F4: Rango Inicial | G4: Rango Final | H4: Formato | I4: Valor por defecto | J4: Regla especial | K4: ¿Auto generado? | L4: ¿Calculado? | M4: ¿Obligatorio? | N4: ¿Sensible? | O4: ¿Identifica al registro? | P4: Descripción | Q4: =A20 -> Autenticar Administrador
A5: Identificador | B5: UUID | C5: 36 | D5: 36 | H5: Formato de un identificador único universal (UUID) | K5: Si | L5: No | M5: Si | N5: Si | O5: Si | P5: Valor único que identifica al administrador de la aplicación Cognicare | Q5: No aplica
A6: Nombres | B6: String | C6: 1 | D6: 200 | H6: Solo letras y espacio | K6: No | L6: No | M6: Si | N6: No | O6: No | P6: Nombre del administrador | Q6: No aplica
A7: Apellidos | B7: String | C7: 1 | D7: 200 | H7: Solo letras y espacio | K7: No | L7: No | M7: Si | N7: No | O7: No | P7: Apellidos del administrador | Q7: No aplica
A8: Tipo Documento | B8: UUID | H8: Formato de un identificador único universal (UUID) | K8: No | L8: No | M8: Si | N8: No | O8: No | P8: Tipo de documento del administrador | Q8: Aplica
A9: Numero Documento | B9: String | C9: 1 | D9: 20 | H9: Solo números | K9: No | L9: No | M9: Si | N9: No | O9: No | P9: Número de documento del administrador | Q9: No aplica
A10: Fecha Inicio | B10: Date | H10: YYYY-MM-DD | K10: No | L10: No | M10: Si | P10: Fecha de inicio del administrador | Q10: No aplica
A11: Fecha Fin | B11: Date | H11: YYYY-MM-DD | K11: No | L11: No | M11: Si | N11: No | O11: No | P11: Fecha de fin del administrador | Q11: No aplica
A13: Combinaciones únicas
A14: Nombre combinación | B14: Descripción | C14: Atributos
A15: Combinación 1 | B15: No pueden haber dos o más administradores con el mismo tipo y numero de documento | C15: tipoDocumento
C16: numeroDocumento
A18: Responsabilidad | C18: Descripción | G18: Entradas | J18: Salida | O18: Políticas (Reglas de Negocio) | Q18: Excepción
G19: Parámetro | H19: Tipo de dato | I19: Descripción | J19: Tipo de Dato | K19: Descripción | O19: Política | P19: Descripción | Q19: Detalle | R19: ¿Qué hago?
A20: Autenticar Administrador | C20: Valida las credenciales de un administrador para concederle acceso al sistema con privilegios elevados. | G20: numeroDocumento | H20: String | I20: Número de documento del administrador, que funciona como su credencial de acceso. | J20: Object | K20: Objeto JSON que contiene el token de acceso y la información del usuario | O20: RN-Admin-01 | P20: El numeroDocumento debe coincidir con un registro en la tabla CC.Administrador | Q20: Credenciales inválidas | R20: Retornar un error con credenciales invalidas o admin desactivado
O21: RN-Admin-02 | P21: El contrato del administrador debe estar activo (fechaFin > fecha actual). | Q21: Datos de entrada inválidos | R21: Retornar un error con credenciales invalidas o admin desactivado
O22: RN-Admin-03 | P22: El token generado debe contener el ID del administrador y el rol "admin". | Q22: Error inesperado del servidor | R22: Retornar un error 500 Internal Server Error

Sheet Estudiante Programa
A1: <-Volver al inicio
A2: Objeto de Dominio: | B2: ='Listado Objetos de Dominio'!A6 -> Estudiante Programa
A3: Descripción: | B3: ='Listado Objetos de Dominio'!B6 -> Objeto de dominio que contiene a los programas por estudiante
A4: Atributo | B4: Tipo de Dato | C4: Longitud mínima | D4: Longitud máxima | E4: Precisión | F4: Rango Inicial | G4: Rango Final | H4: Formato | I4: Valor por defecto | J4: Regla especial | K4: ¿Auto generado? | L4: ¿Calculado? | M4: ¿Obligatorio? | N4: ¿Sensible? | O4: ¿Identifica al registro? | P4: Descripción | Q4: =A18 -> Asociar Programa(s) | R4: =A21 -> Modificar Asociaciones (Durante la Actualización de Estudiante)
A5: Identificador | B5: Alfanumérico | C5: 2 | D5: 50 | H5: Solo Números | K5: Si | L5: No | M5: Si | N5: Si | O5: Si | P5: Valor único que identifica el registro | Q5: Aplica | R5: Aplica
A6: Estudiante | B6: UUID | H6: Formato de un identificador único universal (UUID) | K6: No | L6: No | M6: Si | N6: No | O6: No | P6: Estudiante que pertenece al programa | Q6: Aplica | R6: Aplica
A7: Programa | B7: UUID | H7: Formato de un identificador único universal (UUID) | K7: No | L7: No | M7: Si | N7: No | O7: No | P7: Programa al que pertenece el estudiante | Q7: Aplica | R7: Aplica
A9: Combinaciones únicas
A10: Nombre combinación | B10: Descripción | C10: Atributos
A11: Combinación 1 | B11: No es posible que un estudiante esté dos o más veces en el mismo programa | C11: Estudiante
C12: Programa
A14: NOTA: Estudiante Programa es un objeto que actua de enlace entre Estudiante y Programa, su ciclo de vida ocurre dentro de las operaciones de la entidad Estudiante
A16: Responsabilidad | C16: Descripción | G16: Entradas | J16: Salida | O16: Políticas (Reglas de Negocio) | Q16: Excepción
G17: Parámetro | H17: Tipo de dato | I17: Descripción | J17: Tipo de Dato | K17: Descripción | O17: Política | P17: Descripción | Q17: Detalle | R17: ¿Qué hago?
A18: Asociar Programa(s) | C18: Crea uno o más registros en la tabla EstudiantePrograma para vincular a un estudiante recién creado con sus programas académicos. | G18: estudianteId | H18: UUID | I18: El ID del estudiante recién creado (Acción en base de datos) | O18: RN-EstudiantePrograma-01 | P18: La asociación es única: un estudiante no puede estar inscrito dos veces en el mismo programa. | Q18: Asociación duplicada | R18: La base de datos retorna un error de Unique Violation. La transacción no continua
G19: programaNombres | H19: Array<String> | I19: Lista de nombres de los programas a asociar. | O19: RN-EstudiantePrograma-02 | P19: Cada nombre de programa en la lista debe corresponder a un programa existente en la tabla Programa. | Q19: Programa no encontrado | R19: La transacción principal en base de datos falla, lo que no permite hacer el registro
O20: RN-EstudiantePrograma-03 | P20: Un estudiante debe estar asociado a un mínimo de 1 y un máximo de 2 programas. | Q20: Número de programas inválido | R20: La transacción principal falla, lo que no permite hacer el registro
A21: Modificar Asociaciones (Durante la Actualización de Estudiante) | C21: Reemplaza por completo la lista de programas a los que está asociado un estudiante. | G21: estudianteId | H21: UUID | I21: El ID del estudiante que se está modificando. | O21: RN-EstudiantePrograma-04 | P21: La nueva lista de programas debe cumplir con la regla de mínimo 1 y máximo 2 programas. | Q21: Número de programas inválido | R21: La transacción no permite hacer el cambio
G22: programaNombres | H22: Array<String> | I22: La nueva lista completa de nombres de programas a asociar.

Sheet Entrenador Facultad
A1: <-Volver al inicio
A2: Objeto de Dominio: | B2: ='Listado Objetos de Dominio'!A7 -> Entrenador Facultad
A3: Descripción: | B3: ='Listado Objetos de Dominio'!B7 -> Objeto de dominio que contiene a los entrenadores por facultad
A4: Atributo | B4: Tipo de Dato | C4: Longitud mínima | D4: Longitud máxima | E4: Precisión | F4: Rango Inicial | G4: Rango Final | H4: Formato | I4: Valor por defecto | J4: Regla especial | K4: ¿Auto generado? | L4: ¿Calculado? | M4: ¿Obligatorio? | N4: ¿Sensible? | O4: ¿Identifica al registro? | P4: Descripción | Q4: =A18 -> Asociar Facultad(es) | R4: =A21 -> Modificar Asociaciones
A5: identificador | B5: Alfanumérico | C5: 2 | D5: 50 | H5: Solo Números | K5: Si | L5: No | M5: Si | N5: Si | O5: Si | P5: Valor único que identifica el registro | Q5: Aplica | R5: No aplica
A6: entrenador | B6: UUID | H6: Formato de un identificador único universal (UUID) | K6: No | L6: No | M6: Si | N6: No | O6: No | P6: Entrenador que pertenece a la facultad | Q6: Aplica | R6: No aplica
A7: facultad | B7: UUID | H7: Formato de un identificador único universal (UUID) | K7: No | L7: No | M7: Si | N7: No | O7: No | P7: Facultad a la que pertenece el entrenador | Q7: Aplica | R7: Aplica
A9: Combinaciones únicas
A10: Nombre combinación | B10: Descripción | C10: Atributos
A11: Combinación 1 | B11: No es posible que un entrenador este asignado dos o más veces en la misma facultad | C11: entrenador
C12: facultad
A14: NOTA: Entrenador Facultad es un objeto que actua de enlace entre Entrenador y Facultad, su ciclo de vida ocurre dentro de las operaciones de la entidad Entrenador
A16: Responsabilidad | C16: Descripción | G16: Entradas | J16: Salida | O16: Políticas (Reglas de Negocio) | Q16: Excepción
G17: Parámetro | H17: Tipo de dato | I17: Descripción | J17: Tipo de Dato | K17: Descripción | O17: Política | P17: Descripción | Q17: Detalle | R17: ¿Qué hago?
A18: Asociar Facultad(es) | C18: Crea uno o más registros en la tabla EntrenadorFacultad para vincular a un entrenador recién creado con sus facultades asignadas | G18: entrenadorId | H18: UUID | I18: El ID del entrenador recién creado. | O18: RN-Entrenador Facultad-01 | P18: La asociación es única: un entrenador no puede estar asignado dos veces a la misma facultad. | Q18: Asociación duplicada | R18: La base de datos retorna un error de Unique Violation. La transacción no continua
G19: facultadNombres | H19: Array<String> | I19: Lista de nombres de las facultades a asociar. | O19: RN-Entrenador Facultad-02 | P19: Cada nombre de facultad en la lista debe corresponder a una facultad existente en la tabla Facultad. | Q19: Facultad no encontrada | R19: La transacción principal en base de datos falla, lo que no permite hacer el registro
O20: RN-Entrenador Facultad-03 | P20: Un entrenador debe estar asociado al menos a una facultad. | Q20: Lista de facultades vacía | R20: La transacción principal falla, lo que no permite hacer el registro
A21: Modificar Asociaciones | C21: Reemplaza por completo la lista de facultades a las que está asociado un entrenador. | G21: entrenadorId | H21: UUID | I21: El ID del entrenador que se está modificando | O21: RN-Entrenador Facultad-04 | P21: La nueva lista de facultades debe contener nombres válidos. | Q21: Facultad no encontrada | R21: La transacción principal en base de datos falla, lo que no permite hacer el registro
G22: nuevosNombresFacultades | H22: Array<String> | I22: La nueva lista completa de nombres de facultades a asociar. | Q22: Lista de facultades vacía | R22: La transacción principal falla, lo que no permite hacer el registro

Sheet Entrenador Entrenamiento
A1: <-Volver al inicio
A2: Objeto de Dominio: | B2: ='Listado Objetos de Dominio'!A8 -> Entrenador Entrenamiento
A3: Descripción: | B3: ='Listado Objetos de Dominio'!B8 -> Objeto de dominio que corresponde a la tabla intermedia de la relación de muchos a muchos entre entrenador y entrenamiento cognitivo
A4: Atributo | B4: Tipo de Dato | C4: Longitud mínima | D4: Longitud máxima | E4: Precisión | F4: Rango Inicial | G4: Rango Final | H4: Formato | I4: Valor por defecto | J4: Regla especial | K4: ¿Auto generado? | L4: ¿Calculado? | M4: ¿Obligatorio? | N4: ¿Sensible? | O4: ¿Identifica al registro? | P4: Descripción | Q4: =A18 -> Asociar Entrenador | R4: =A21 -> Modificar Asociación
A5: identificador | B5: Alfanumérico | D5: 50 | H5: Solo Números | K5: Si | L5: No | M5: Si | N5: Si | O5: Si | P5: Valor único que identifica el registro | Q5: Aplica | R5: No aplica
A6: entrenador | B6: UUID | H6: Formato de un identificador único universal (UUID) | K6: No | L6: No | M6: Si | N6: No | O6: No | P6: Entrenador que supervisa el entrenamiento cognitivo | Q6: Aplica | R6: No aplica
A7: entrenamientoCognitivo | B7: UUID | H7: Formato de un identificador único universal (UUID) | K7: No | L7: No | M7: Si | N7: No | O7: No | P7: Entrenamiento cognitivo sueprvisado por el entrenador | Q7: Aplica | R7: Aplica
A9: Combinaciones únicas
A10: Nombre combinación | B10: Descripción | C10: Atributos
A11: Combinación 1 | B11: No es posible que un entrenador supervise dos o más veces el mismo entrenamiento cognitivo | C11: entrenador
C12: entrenamientoCognitivo
A14: NOTA: Entrenador Entrenamiento es un objeto que actua de enlace entre Entrenador y Entrenamiento Cognitivo, su ciclo de vida ocurre dentro de las operaciones de la Entrenamiento Cognitivo
A16: Responsabilidad | C16: Descripción | G16: Entradas | J16: Salida | O16: Políticas (Reglas de Negocio) | Q16: Excepción
G17: Parámetro | H17: Tipo de dato | I17: Descripción | J17: Tipo de Dato | K17: Descripción | O17: Política | P17: Descripción | Q17: Detalle | R17: ¿Qué hago?
A18: Asociar Entrenador | C18: Crea un registro en la tabla EntrenadorEntrenamiento para asignar un entrenador a un plan de entrenamiento cognitivo recién creado. | G18: entrenadorId | H18: UUID | I18: ID del entrenador a asignar. | O18: RN-Entrenador Entrenamiento-01 | P18: La asociación es única: un entrenador no puede estar asignado dos veces al mismo entrenamiento cognitivo. | Q18: Asociación duplicada | R18: La base de datos retorna un error de Unique Violation. La transacción no continua
G19: entrenamientoCognitivoId | H19: UUID | I19: El ID del entrenamiento recién creado. | O19: RN-Entrenador Entrenamiento-02 | P19: El entrenador y el entrenamiento cognitivo deben existir en sus respectivas tablas. | Q19: Entrenador o Entrenamiento no encontrado | R19: La base de datos no deja continuar con la transacción.
O20: RN-Entrenador Entrenamiento-03 | P20: La operación de creación principal solo puede ser realizada por un rol autorizado. | Q20: Rol no autorizado | R20: La transacción principal no permite hacer el registro
A21: Modificar Asociación | C21: Cambia el entrenador asignado a un entrenamiento cognitivo existente. | G21: entrenamientoCognitivoId | H21: UUID | I21: El ID del entrenamiento que se está modificando. | O21: RN-Entrenador Entrenamiento-03 | P21: La operación de creación principal solo puede ser realizada por un rol autorizado. | Q21: Rol no autorizado | R21: La transacción principal no permite hacer el registro
G22: nuevoEntrenadorId | H22: UUID | I22: El ID del nuevo entrenador a asignar.

Sheet Entrenamiento Cognitivo
A1: <-Volver al inicio
A2: Objeto de Dominio: | B2: ='Listado Objetos de Dominio'!A9 -> Entrenamiento Cognitivo
A3: Descripción: | B3: ='Listado Objetos de Dominio'!B9 -> Objeto de dominio encargado de contener el plan de entrenamiento que desarrolla el estudiante
A4: Atributo | B4: Tipo de Dato | C4: Longitud mínima | D4: Longitud máxima | E4: Precisión | F4: Rango Inicial | G4: Rango Final | H4: Formato | I4: Valor por defecto | J4: Regla especial | K4: ¿Auto generado? | L4: ¿Calculado? | M4: ¿Obligatorio? | N4: ¿Sensible? | O4: ¿Identifica al registro? | P4: Descripción | Q4: =A17 -> Crear Entrenamiento | R4: =A23 -> Modificar Entrenamientonto | S4: =A30 -> Consultar Detalle | T4: =A33 -> Finalizar Sesión | U4: =A37 -> Finalizar Asignación | V4: =A40 -> Consultar Progreso
A5: identificador | B5: UUID | C5: 36 | D5: 36 | H5: Formato de un identificador único universal (UUID) | K5: Si | L5: No | M5: Si | N5: Si | O5: Si | P5: Valor único para identificar el registro del entrenamiento cognitivo | Q5: Aplica | R5: No aplica | S5: Filtra/No mostrar | T5: No aplica | U5: No aplica | V5: No aplica
A6: estudiante | B6: UUID | H6: Formato de un identificador único universal (UUID) | K6: No | L6: No | M6: Si | N6: Si | O6: Si | P6: Estudiante que ejecuta el entrenamiento cognitivo | Q6: Aplica | R6: No aplica | S6: Filtra/Mostrar | T6: No aplica | U6: No aplica | V6: No aplica
A7: fechaInicio | B7: Date | H7: YYYY-MM-DD | K7: Si | L7: No | M7: Si | N7: No | O7: No | P7: Fecha en la que se inicia el entrenamiento cognitivo | Q7: Aplica | R7: No aplica | S7: Filtra/Mostrar | T7: No aplica | U7: No aplica | V7: No aplica
A8: fechaFin | B8: Date | H8: YYYY-MM-DD | K8: No | L8: No | M8: No | N8: No | O8: No | P8: Fecha en la que finaliza el entrenamiento cognitivo | Q8: Aplica | R8: Aplica | S8: Filtra/Mostrar | T8: No aplica | U8: No aplica | V8: No aplica
A9: estado | B9: UUID | H9: Formato de un identificador único universal (UUID) | K9: Si | L9: Si | M9: Si | N9: No | O9: No | P9: Estado actual del entrenamiento cognitivo | Q9: Aplica | R9: Aplica | S9: Filtra/Mostrar | T9: No aplica | U9: No aplica | V9: No aplica
A11: Combinaciones únicas
A12: Nombre combinación | B12: Descripción | C12: Atributos
A13: Combinación 1 | B13: No es posible que dos o más entrenamientos tengan al mismo estudiante | C13: =A6 -> estudiante
A15: Responsabilidad | C15: Descripción | G15: Entradas | J15: Salida | O15: Políticas (Reglas de Negocio) | Q15: Excepción
G16: Parámetro | H16: Tipo de dato | I16: Descripción | J16: Tipo de Dato | K16: Descripción | O16: Política | P16: Descripción | Q16: Detalle | R16: ¿Qué hago?
A17: Crear Entrenamiento | C17: Crea un nuevo plan de entrenamiento para un estudiante, asignando un entrenador y un conjunto inicial de variables cognitivas. | G17: siglaTipoDocEstudiante | H17: String | I17: Sigla del tipo de documento del estudiante | J17: Object | K17: Objeto JSON que confirma la creación del entrenamiento. | O17: RN-Entrenamiento Cognitivo-01 | P17: La operación solo puede ser realizada por un rol autorizado | Q17: Rol no autorizado | R17: Retornar un error 401 Unauthorized o Forbidden.
G18: numeroDocEstudiante | H18: String | I18: Número de documento del estudiante. | O18: RN-Entrenamiento Cognitivo-02 | P18: Un estudiante solo puede tener un entrenamiento cognitivo a la vez | Q18: Estudiante ya tiene entrenamiento | R18: Retornar un error 409 Conflict
G19: siglaTipoDocEntrenador | H19: String | I19: Sigla del tipo de documento del entrenador | O19: RN-Entrenamiento Cognitivo-03 | P19: El estudiante, el entrenador y todas las variables cognitivas deben existir. | Q19: Entidad no encontrada | R19: No permitir continuar la transacción, 404 Not Found
G20: numeroDocEntrenador | H20: String | I20: Número de documento del entrenador. | O20: RN-Entrenamiento Cognitivo-04 | P20: Se debe especificar al menos una variable cognitiva para el entrenamiento. | Q20: Datos de entrada inválidos | R20: Bad Request
G21: fechaFinEntrenamiento | H21: Date | I21: Fecha de finalización programada para el entrenamiento. | Q21: Error inesperado del servidor | R21: Retornar un error 500 Internal Server Error
G22: variablesCognitivas | H22: Array<String> | I22: Lista de nombres de las variables a entrenar.
A23: Modificar Entrenamientonto | C23: Actualiza un entrenamiento existente, permitiendo añadir/quitar variables, cambiar al entrenador o extender la fecha de fin. | G23: siglaTipoDocEstudiante | H23: String | I23: Sigla del tipo de documento del estudiante | J23: Object | K23: Objeto JSON que confirma la creación del entrenamiento. | O23: RN-Entrenamiento Cognitivo-01 | P23: La operación solo puede ser realizada por un rol autorizado | Q23: Rol no autorizado | R23: Retornar un error 401 Unauthorized o Forbidden.
G24: numeroDocEstudiante | H24: String | I24: Número de documento del estudiante. | O24: RN-Entrenamiento Cognitivo-05 | P24: El entrenamiento solo puede modificarse si su estado es "Por Iniciar" o "En Progreso". | Q24: Estudiante ya tiene entrenamiento | R24: Retornar un error 409 Conflict
G25: variablesAAgregar | H25: Array<String> | I25: (Opcional) Lista de nombres de variables a añadir. | O25: RN-Entrenamiento Cognitivo-06 | P25: No se puede dejar un entrenamiento sin variables cognitivas asignadas | Q25: Entidad no encontrada | R25: No permitir continuar la transacción, 404 Not Found
G26: variablesARemover | H26: Array<String> | I26: (Opcional) Lista de nombres de variables a quitar. | O26: RN-Entrenamiento Cognitivo-07 | P26: Las variables a remover no deben estar en un estado final ("Finalizado", "Abandono"). | Q26: Datos de entrada inválidos | R26: Bad Request
G27: siglaTipoDocNuevoEntrenador | H27: String | I27: (Opcional) Sigla del documento del nuevo entrenador. | Q27: Error inesperado del servidor | R27: Retornar un error 500 Internal Server Error
G28: numeroDocNuevoEntrenador | H28: String | I28: (Opcional) Número de documento del nuevo entrenador.
G29: nuevaFechaFinEntrenamiento | H29: Date | I29: (Opcional) Nueva fecha de fin del entrenamiento.
A30: Consultar Detalle | C30: Obtiene los detalles de un entrenamiento cognitivo para un estudiante específico, incluyendo el estado de cada variable asignada. | G30: tipoDocumento | H30: String | I30: Sigla del tipo de documento del estudiante. | J30: Object | K30: Objeto JSON que confirma la creación del entrenamiento. | O30: RN-Entrenamiento Cognitivo-08 | P30: El entrenamiento cognitivo debe existir | Q30: Entrenamiento no encontrado | R30: Retornar un 200 OK con un mensaje indicando que no se encontró entrenamiento y un array de datos vacío.
G31: numeroDocumento | H31: String | I31: Número de documento del estudiante. | Q31: Datos de entrada inválidos | R31: Bad Request
Q32: Error inesperado del servidor | R32: Retornar un error 500 Internal Server Error
A33: Finalizar Sesión | C33: Marca una sesión como "Finalizada" y actualiza las métricas y el nivel del estudiante para esa variable. | G33: idSesion | H33: UUID | I33: ID de la sesión de entrenamiento a finalizar. | J33: Object | K33: Objeto JSON que confirma la finalización. | O33: RN-Entrenamiento Cognitivo-01 | P33: La operación solo puede ser realizada por un rol autorizado | Q33: Rol no autorizado | R33: Retornar un error 401 Unauthorized o Forbidden.
G34: nuevasMetricas | H34: Object | I34: Objeto JSON con las métricas de rendimiento de la sesión. | O34: RN-Entrenamiento Cognitivo-09 | P34: La sesión debe existir y estar en estado "En Progreso" | Q34: Sesión no encontrada o en estado incorrecto | R34: Retornar un error 404 Not Found o 400 Bad Request.
G35: nuevoNivelInicial | H35: Object | I35: Objeto JSON con el nuevo estado/nivel del estudiante tras la sesión. | O35: RN-Entrenamiento Cognitivo-10 | P35: Los objetos nuevasMetricas y nuevoNivelInicial deben ser JSON válidos. | Q35: Datos de entrada inválidos | R35: Retornar un error 400 Bad Request
Q36: Error inesperado del servidor | R36: Retornar un error 500 Internal Server Error
A37: Finalizar Asignación | C37: Marca una asignación de variable completa como "Finalizada". Esto puede desencadenar la finalización del entrenamiento general. | G37: idAsignacion | H37: UUID | I37: ID de la asignación de variable a finalizar. | J37: Object | K37: Objeto JSON que confirma la finalización. | O37: RN-Entrenamiento Cognitivo-01 | P37: La operación solo puede ser realizada por un rol autorizado | Q37: Rol no autorizado | R37: Retornar un error 401 Unauthorized o Forbidden.
O38: RN-Entrenamiento Cognitivo-09 | P38: La asignación de variable debe existir y estar en estado "En Progreso". | Q38: Asignación no encontrada o en estado incorrecto | R38: Retornar un error 404 Not Found o 400 Bad Request.
O39: RN-Entrenamiento Cognitivo-11 | P39: Si todas las variables activas están finalizadas, el estado del EntrenamientoCognitivo padre se actualiza a "Finalizado" | Q39: Error inesperado del servidor | R39: Retornar un error 500 Internal Server Error
A40: Consultar Progreso | C40: Obtiene el detalle completo del progreso de una variable asignada, incluyendo métricas y el historial de todas sus sesiones. | G40: asignacionId | H40: UUID | I40: ID de la asignación de la variable a consultar. | J40: Object | K40: Objeto JSON con los datos del progreso. | O40: RN-Entrenamiento Cognitivo-01 | P40: La operación solo puede ser realizada por un rol autorizado | Q40: Rol no autorizado | R40: Retornar un error 401 Unauthorized o Forbidden.
O41: RN-Entrenamiento Cognitivo-12 | P41: La consulta se realiza contra la vista ProgresoVariableUV | Q41: Asignación no encontrada | R41: Retornar un error 404 Not Found
Q42: Error inesperado del servidor | R42: Retornar un error 500 Internal Server Error

Sheet Asignación Variable Cognitiva
A1: <-Volver al inicio
A2: Objeto de Dominio: | B2: ='Listado Objetos de Dominio'!A11 -> Asignación Variable
A3: Descripción: | B3: ='Listado Objetos de Dominio'!B11 -> Objeto de dominio el cual anuncia el estado de las diferentes variables cognitivas a las que el estudiante tiene acceso
A4: Atributo | B4: Tipo de Dato | C4: Longitud mínima | D4: Longitud máxima | E4: Precisión | F4: Rango Inicial | G4: Rango Final | H4: Formato | I4: Valor por defecto | J4: Regla especial | K4: ¿Auto generado? | L4: ¿Calculado? | M4: ¿Obligatorio? | N4: ¿Sensible? | O4: ¿Identifica al registro? | P4: Descripción | Q4: =A19 -> Crear Asignación | R4: =A22 -> Abandonar Asignación | S4: =A26 -> Reactivar Asignación | T4: =A30 -> Finalizar Asignación
A5: Identificador | B5: UUID | C5: 36 | D5: 36 | H5: Formato de un identificador único universal (UUID) | K5: Si | L5: No | M5: Si | N5: Si | O5: Si | P5: Valor único para identificar el registro del entrenamiento cognitivo | Q5: No aplica | R5: Filtra/No mostrar | S5: Filtra/No mostrar | T5: Aplica
A6: entrenamientoCognitivo | B6: UUID | H6: Formato de un identificador único universal (UUID) | K6: No | L6: No | M6: Si | N6: Si | O6: Si | P6: Atributo el cual hace referencia al entrenamiento cognitivo al cual un estudiante esta registrado | Q6: Aplica | R6: Filtra/Mostrar | S6: Filtra/Mostrar | T6: Aplica
A7: tipoVariableCognitiva | B7: UUID | H7: Formato de un identificador único universal (UUID) | K7: No | L7: No | M7: Si | N7: No | O7: No | P7: Tipo de variable cognitiva asignada al entrenamiento cognitivo | Q7: Aplica | R7: Filtra/Mostrar | S7: Filtra/Mostrar | T7: Aplica
A8: progreso | B8: JSON | H8: Formato con la tarea y el nivel realizado en la última sesión | K8: No | L8: No | M8: No | N8: No | O8: No | P8: Atributo que representa el estado en el que se encuentra cada uno de los módulos de la aplicación | Q8: Aplica | R8: Filtra/Mostrar | S8: Filtra/Mostrar | T8: No aplica
A9: metricas | B9: JSON | H9: Formato con la tarea, nivel, numero de aciertos, numero de errores y el estado | K9: No | L9: No | M9: No | N9: Si | O9: No | P9: Resultados generados por las variables cognitivas asignadas | Q9: Aplica | R9: Filtra/Mostrar | S9: Filtra/Mostrar | T9: Aplica
A10: estadoVariableCognitiva | B10: UUID | H10: Formato de un identificador único universal (UUID) | I10: En Progreso | K10: No | L10: Si | M10: Si | N10: No | O10: No | P10: Estado de la variable cognitiva | Q10: Aplica | R10: Filtra/Mostrar | S10: Filtra/Mostrar | T10: Aplica
A12: Combinaciones únicas
A13: Nombre combinación | B13: Descripción | C13: Atributos
A14: Combinación 1 | B14: Una variable cognitiva no puede estar asignada dos o más veces a un entrenamiento cognitivo | C14: =A6 -> entrenamientoCognitivo
C15: =A7 -> tipoVariableCognitiva
A17: Responsabilidad | C17: Descripción | G17: Entradas | J17: Salida | O17: Políticas (Reglas de Negocio) | Q17: Excepción
G18: Parámetro | H18: Tipo de dato | I18: Descripción | J18: Tipo de Dato | K18: Descripción | O18: Política | P18: Descripción | Q18: Detalle | R18: ¿Qué hago?
A19: Crear Asignación | C19: Crea uno o más registros en AsignacionVariable para vincular un entrenamiento con las variables cognitivas seleccionadas. | G19: entrenamientoCognitivoId | H19: UUID | I19: El ID del entrenamiento recién creado. | O19: RN-Asignacion-01 | P19: La asociación es única: un entrenamiento no puede tener la misma variable cognitiva asignada dos veces. | Q19: Asignación duplicada | R19: La base de datos retorna un error de unique violation.
G20: variablesCognitivas | H20: UUID | I20: Lista de nombres de las variables a asignar | O20: RN-Asignacion-02 | P20: Cada variable cognitiva debe existir y estar activa en la tabla VariableCognitiva. | Q20: Variable no encontrada o inactiva | R20: La función de la base de datos no permite hacer la transacción.
O21: RN-Asignacion-03 | P21: La asignación se crea con el estado "Por Iniciar".
A22: Abandonar Asignación | C22: Cambia el estado de una asignación de variable a "Abandono". | G22: siglaDocumento | H22: String | I22: Sigla del tipo de documento del estudiante. | J22: Object | K22: Objeto JSON que confirma el abandono. | O22: RN-Asignacion-04 | P22: Requiere un token de usuario autenticado. | Q22: Token inválido | R22: Retornar un error 401 Unauthorized.
G23: numeroDocumento | H23: String | I23: Número de documento del estudiante. | O23: RN-Asignacion-05 | P23: El entrenamiento del estudiante debe estar en estado "Por Iniciar" o "En Progreso" | Q23: Entrenamiento no modificable | R23: Retornar un error 400 Bad Request.
G24: idVariableCognitiva | H24: UUID | I24: ID de la variable cognitiva cuya asignación se abandonará. | O24: RN-Asignacion-06 | P24: Si todas las variables de un entrenamiento están en "Abandono", el entrenamiento padre también se marca como "Abandono" | Q24: Asignación no encontrada | R24: Retornar un error 404 Not Found
Q25: Error inesperado del servidor | R25: Retornar un error 500 Internal Server Error
A26: Reactivar Asignación | C26: Cambia el estado de una asignación de "Abandono" de nuevo a "Por Iniciar". | G26: siglaDocumento | H26: String | I26: Sigla del tipo de documento del estudiante. | J26: Object | K26: Objeto JSON que confirma la reactivación. | O26: RN-Asignacion-04 | P26: Requiere un token de usuario autenticado. | Q26: Token inválido | R26: Retornar un error 401 Unauthorized.
G27: numeroDocumento | H27: String | I27: Número de documento del estudiante. | O27: RN-Asignacion-07 | P27: La asignación de variable debe existir y estar en estado "Abandono" | Q27: Asignación no está abandonada | R27: Retornar un error 400 Bad Request.
G28: idVariableCognitiva | H28: UUID | I28: ID de la variable cognitiva cuya asignación se reactivará. | O28: RN-Asignacion-08 | P28: Si el entrenamiento padre estaba en "Abandono", se reactiva a "Por Iniciar". | Q28: Asignación no encontrada | R28: Retornar un error 404 Not Found
Q29: Error inesperado del servidor | R29: Retornar un error 500 Internal Server Error
A30: Finalizar Asignación | C30: Marca una asignación de variable como "Finalizada", indicando que el estudiante completó el entrenamiento para esa variable. | G30: idAsignacion | H30: UUID | I30: ID de la asignación de variable a finalizar. | J30: Object | K30: Objeto JSON que confirma la finalización | O30: RN-Asignacion-04 | P30: Requiere un token de usuario autenticado. | Q30: Token inválido | R30: Retornar un error 401 Unauthorized.
O31: RN-Asignacion-08 | P31: La asignación de variable debe existir y estar en estado "En Progreso". | Q31: Asignación no encontrada o en estado incorrecto | R31: Retornar un error 404 Not Found o 400 Bad Request.
O32: RN-Asignacion-09 | P32: Si todas las variables activas están finalizadas, el estado del EntrenamientoCognitivo padre se actualiza a "Finalizado". | Q32: Error inesperado del servidor | R32: Retornar un error 500 Internal Server Error

Sheet Sesion Entrenamiento
A1: <-Volver al inicio
A2: Objeto de Dominio: | B2: ='Listado Objetos de Dominio'!A5 -> Administrador
A3: Descripción: | B3: ='Listado Objetos de Dominio'!B5 -> Objeto de dominio correspondiente a los administrador de la aplicación Cognicare
A4: Atributo | B4: Tipo de Dato | C4: Longitud mínima | D4: Longitud máxima | E4: Precisión | F4: Rango Inicial | G4: Rango Final | H4: Formato | I4: Valor por defecto | J4: Regla especial | K4: ¿Auto generado? | L4: ¿Calculado? | M4: ¿Obligatorio? | N4: ¿Sensible? | O4: ¿Identifica al registro? | P4: Descripción | Q4: =A20 -> Crear Sesión | R4: =A24 -> Iniciar Sesión | S4: =A26 -> Finalizar Sesión | T4: =A29 -> Actualizar Observación
A5: identificador | B5: UUID | C5: 36 | D5: 36 | H5: Formato de Identificador Único Universal (UUID) | K5: Si | L5: No | M5: Si | N5: Si | O5: Si | P5: Valor único que identifica a la sesion de entrenamiwento | Q5: Aplica | R5: Filtra/No mostrar | S5: No aplica | T5: No aplica
A6: asignacionVariable | B6: UUID | H6: Formato de Identificador Único Universal (UUID) | K6: No | L6: No | M6: Si | N6: Si | O6: No | P6: Variable a la cual se creo la sesion de entrenamiento | Q6: Aplica | R6: No aplica | S6: No aplica | T6: No aplica
A7: numeroSesion | B7: String | H7: Solo numeros | K7: Si | L7: No | M7: Si | N7: No | O7: No | P7: Numero de la sesion de entrenamiento | Q7: Aplica | R7: Aplica | S7: No aplica | T7: No aplica
A8: fechaInicio | B8: Date | H8: YYYY-MM-DD HH:mm:ss | K8: No | L8: No | M8: Si | N8: No | O8: No | P8: Fecha de inicio de la sesion seleccionada por el entrenador | Q8: Aplica | R8: Aplica | S8: No aplica | T8: No aplica
A9: fechaFin | B9: Date | H9: YYYY-MM-DD HH:mm:ss | K9: No | L9: No | M9: Si | N9: No | O9: No | P9: Fecha de finalizacion de la sesion | Q9: Aplica | R9: Aplica | S9: Aplica | T9: No aplica
A10: observacion | B10: String | C10: 0 | D10: 500 | K10: No | L10: No | M10: No | N10: No | O10: No | P10: Campo libre para las observaciones que realice el entrenador durante la sesión de entrenamiento | Q10: No aplica | R10: No aplica | S10: No aplica | T10: Aplica
A11: estado | B11: UUID | H11: Formato de Identificador Único Universal (UUID) | I11: Por Iniciar | K11: Si | L11: Si | M11: Si | N11: No | O11: No | P11: Estado de la sesion de entrenamiento | Q11: Aplica | R11: Aplica | S11: Aplica | T11: No aplica
A13: Combinaciones únicas
A14: Nombre combinación | B14: Descripción | C14: Atributos
A15: Combinación 1 | B15: No puede haber dos o más sesiones con el mismo numero de sesion | C15: =A6 -> asignacionVariable
C16: =A7 -> numeroSesion
A18: Responsabilidad | C18: Descripción | G18: Entradas | J18: Salida | O18: Políticas (Reglas de Negocio) | Q18: Excepción
G19: Parámetro | H19: Tipo de dato | I19: Descripción | J19: Tipo de Dato | K19: Descripción | O19: Política | P19: Descripción | Q19: Detalle | R19: ¿Qué hago?
A20: Crear Sesión | C20: Agenda una nueva sesión de trabajo para un estudiante en una variable cognitiva específica. | G20: siglaTipoDocEstudiante | H20: String | I20: Sigla del tipo de documento del estudiante. | J20: Object | K20: Objeto JSON que confirma la creación de la sesión. | O20: RN-Sesion-01 | P20: La operación solo puede ser realizada por un rol autorizado | Q20: Rol no autorizado | R20: Retornar un error 401 o 403
G21: numeroDocEstudiante | H21: String | I21: Número de documento del estudiante. | O21: RN-Sesion-02 | P21: El entrenamiento general y la asignación de variable del estudiante deben estar en un estado que permita nuevas sesiones ("Por Iniciar" o "En Progreso"). | Q21: Entrenamiento/Asignación no modificable | R21: Retornar un error 400 Bad Request.
G22: nombreVariableCognitiva | H22: String | I22: Nombre de la variable para la cual se crea la sesión. | O22: RN-Sesion-03 | P22: La sesión se crea con un estado por defecto de "Por Iniciar". | Q22: Estudiante o Asignación de Variable no encontrados | R22: Retornar un error 404 Not Found
G23: fechaInicio | H23: Date | I23: Fecha y hora de inicio de la sesión | O23: RN-Sesion-04 | P23: El número de sesión es autoincremental para esa variable específica. | Q23: Error inesperado del servidor | R23: Retornar un error 500 Internal Server Error
A24: Iniciar Sesión | C24: Cambia el estado de una sesión de "Por Iniciar" a "En Progreso". | G24: idSesion | H24: UUID | I24: ID de la sesión a iniciar. | J24: Object | K24: Objeto JSON que confirma el inicio de la sesión. | O24: RN-Sesion-05 | P24: La sesión debe existir y estar en estado "Por Iniciar". | Q24: Sesión no encontrada o en estado incorrecto | R24: Retornar un error 404 Not Found o 400 Bad Request.
O25: RN-Sesion-06 | P25: Al iniciar la sesión, el estado de la AsignacionVariable y del EntrenamientoCognitivo padres se actualiza a "En Progreso". | Q25: Error inesperado del servidor | R25: Error inesperado del servidor Retornar un error 500 Internal Server Error
A26: Finalizar Sesión | C26: Marca una sesión como "Finalizada" y actualiza las métricas y el nivel del estudiante para esa variable. | G26: idSesion | H26: UUID | I26: ID de la sesión de entrenamiento a finalizar. | J26: Object | K26: Objeto JSON que confirma la finalización. | O26: RN-Sesion-07 | P26: La sesión debe existir y estar en estado "En Progreso". | Q26: Sesión no encontrada o en estado incorrecto | R26: Retornar un error 404 Not Found o 400 Bad Request.
G27: nuevasMetricas | H27: JSON | I27: Objeto JSON con las métricas de rendimiento de la sesión. | O27: RN-Sesion-08 | P27: Los objetos nuevasMetricas y nuevoNivelInicial deben ser JSON válidos | Q27: Datos de entrada inválidos | R27: Retornar un error 400 Bad Request.
G28: nuevoNivelInicial | H28: JSON | I28: Objeto JSON con el nuevo estado/nivel del estudiante tras la sesión. | O28: RN-Sesion-09 | P28: La operación actualiza los campos metricas y nivelInicial en la tabla AsignacionVariable padre. | Q28: Error inesperado del servidor | R28: Retornar un error 500 Internal Server Error
A29: Actualizar Observación | C29: Permite a un entrenador añadir o modificar comentarios en una sesión que ya ha concluido. | G29: idSesion | H29: UUID | I29: ID de la sesión a modificar. | J29: Object | K29: Objeto JSON que confirma la actualización. | O29: RN-Sesion-01 | P29: La operación solo puede ser realizada por un rol autorizado | Q29: Rol no autorizado | R29: Retornar un error 401 o 403
G30: nuevaObservacion | H30: String | I30: El nuevo texto para la observación (máx. 500 caracteres). | O30: RN-Sesion-10 | P30: La sesión no debe estar en estado "Por Iniciar" o "En Progreso". Solo se pueden añadir observaciones a sesiones concluidas | Q30: Estado de sesión no permite observaciones | R30: Retornar un error 400 Bad Request.
Q31: Sesión no encontrada | R31: Retornar un error 404 Not Found
Q32: Error inesperado del servidor | R32: Retornar un error 500 Internal Server Error

Sheet Variable Cognitiva
A1: <-Volver al inicio
A2: Objeto de Dominio: | B2: ='Listado Objetos de Dominio'!A12 -> Variable Cognitiva
A3: Descripción: | B3: ='Listado Objetos de Dominio'!B12 -> Objeto de dominio que contiene las diferentes variables cognitivas de la aplicacion
A4: Atributo | B4: Tipo de Dato | C4: Longitud mínima | D4: Longitud máxima | E4: Precisión | F4: Rango Inicial | G4: Rango Final | H4: Formato | I4: Valor por defecto | J4: Regla especial | K4: ¿Auto generado? | L4: ¿Calculado? | M4: ¿Obligatorio? | N4: ¿Sensible? | O4: ¿Identifica al registro? | P4: Descripción | Q4: =A17 -> Listar Variables
A5: dentificador | B5: UUID | C5: 36 | D5: 36 | H5: Formato de un identificador único universal (UUID) | J5: Quitar espacios al inicio y al final | K5: Si | L5: No | M5: Si | N5: Si | O5: Si | P5: Valor único para identificar el registro del entrenamiento cognitivo | Q5: Filtra/Mostrar
A6: nombre | B6: String | C6: 5 | D6: 20 | H6: Solo letras y espacios | J6: Quitar espacios al inicio y al final | K6: No | L6: No | M6: Si | N6: No | O6: No | P6: Nombre de la variable cognitiva | Q6: Filtra/Mostrar
A7: descripcion | B7: String | C7: 5 | D7: 50 | H7: Solo letras y espacios | J7: Quitar espacioas al inicio y al final | K7: No | L7: No | M7: Si | N7: No | O7: No | P7: Descripcion de la variable cognitiva | Q7: Filtra/Mostrar
A8: estado | B8: String | H8: Formato de un identificador único universal (UUID) | I8: Activo | K8: No | L8: No | M8: Si | N8: Si | O8: No | P8: Estado de activación de la variable cognitiva | Q8: Filtra/Mostrar
A10: Combinaciones únicas
A11: Nombre combinación | B11: Descripción | C11: Atributos
A12: Combinacion 1 | B12: No puede haber una variable con el mismo nombre | C12: =A6 -> nombre
A13: Combinacion 2 | B13: No puede haber una variable la misma descripción | C13: =A7 -> descripcion
A15: Responsabilidad | C15: Descripción | G15: Entradas | J15: Salida | O15: Políticas (Reglas de Negocio) | Q15: Excepción
G16: Parámetro | H16: Tipo de dato | I16: Descripción | J16: Tipo de Dato | K16: Descripción | O16: Política | P16: Descripción | Q16: Detalle | R16: ¿Qué hago?
A17: Listar Variables | C17: Obtiene una lista de todas las variables cognitivas disponibles en el sistema para ser usadas en los entrenamientos. | I17: No se requieren parámetros de entrada. | J17: Object | K17: Objeto JSON que contiene la lista de variables cognitivas. | O17: RN-Variable-01 | P17: Requiere un token de usuario autenticado | Q17: Token inválido | R17: Retornar un error 401 Unauthorized.
O18: RN-Variable-02 | P18: La consulta se realiza contra la vista ObtenerEntrenamientoCognitivosUV | Q18: Error inesperado del servidor | R18: Retornar un error 500 Internal Server Error
O19: =A23 -> 0

Sheet Tipo Documento
A1: <-Volver al inicio
A2: Objeto de Dominio: | B2: ='Listado Objetos de Dominio'!A13 -> Tipo Documento
A3: Descripción: | B3: ='Listado Objetos de Dominio'!B13 -> Objeto de dominio que contiene los diferentes documentos de identidad válidos
A4: Atributo | B4: Tipo de Dato | C4: Longitud mínima | D4: Longitud máxima | E4: Precisión | F4: Rango Inicial | G4: Rango Final | H4: Formato | I4: Valor por defecto | J4: Regla especial | K4: ¿Auto generado? | L4: ¿Calculado? | M4: ¿Obligatorio? | N4: ¿Sensible? | O4: ¿Identifica al registro? | P4: Descripción | Q4: =A16 -> Listar Tipos
A5: identificador | B5: UUID | C5: 36 | D5: 36 | H5: Formato de Identificador Único Universal (UUID) | K5: Si | L5: No | M5: Si | N5: Si | O5: Si | P5: Valor único que identifica el tipo de documento | Q5: Filtra/No mostrar
